Workbook

Sheet Matriz Interior Izquierda PDC-D
A3: Fusibles | H3: =VLOOKUP(H4,'Acomodos Modularidades'!$A$2:$B$211,2,FALSE) -> A2965400909 | I3: =VLOOKUP(I4,'Acomodos Modularidades'!$A$2:$B$211,2,FALSE) -> A2965402613 | J3: =VLOOKUP(J4,'Acomodos Modularidades'!$A$2:$B$211,2,FALSE) -> A2965400008 | K3: =VLOOKUP(K4,'Acomodos Modularidades'!$A$2:$B$211,2,FALSE) -> A2965409911 | L3: =VLOOKUP(L4,'Acomodos Modularidades'!$A$2:$B$211,2,FALSE) -> A2965404500 | M3: =VLOOKUP(M4,'Acomodos Modularidades'!$A$2:$B$211,2,FALSE) -> A2965404700 | N3: =VLOOKUP(N4,'Acomodos Modularidades'!$A$2:$B$211,2,FALSE) -> A2965404900 | O3: =VLOOKUP(O4,'Acomodos Modularidades'!$A$2:$B$211,2,FALSE) -> A2965405100 | ... HI3: =VLOOKUP(HI4,'Acomodos Modularidades'!$A$2:$B$211,2,FALSE) -> A2965406419
A4: Subensamble | B4: kurzname | C4: Descripcion | D4: # Mercedez | E4: Oracle (s) | F4: Variante | G4: Amp | H4: V1 | I4: V2 | J4: V6 | K4: V8 | L4: V9 | M4: V10 | N4: V11 | O4: V12 | P4: V13 | Q4: V14 | R4: V15 | S4: V16 | T4: V17 | U4: V18 | V4: V19 | W4: V20 | X4: V23 | Y4: V26 | Z4: V29 | AA4: V30 | AB4: V31 | AC4: V32 | AD4: V33 | AE4: V34 | AF4: V38 | AG4: V41 | AH4: V42 | AI4: V43 | AJ4: V44 | AK4: V45 | AL4: V46 | AM4: V48 | AN4: V49 | AO4: V50 | AP4: V51 | AQ4: V60 | AR4: V62 | AS4: V63 | AT4: V65 | AU4: V68 | AV4: V69 | AW4: V70 | AX4: V71 | AY4: V73 | AZ4: V74 | BA4: V75 | BB4: V76 | BC4: V77 | BD4: V79 | BE4: V81 | BF4: V83 | BG4: V86 | BH4: V89 | BI4: V91 | BJ4: V93 | BK4: V94 | BL4: V96 | BM4: V97 | BN4: V100 | BO4: V102 | BP4: V103 | BQ4: V105 | BR4: V106 | BS4: V110 | BT4: V111 | BU4: V132 | BV4: V133 | BW4: V134 | BX4: V135 | BY4: V136 | BZ4: V137 | CA4: V138 | CB4: V139 | CC4: V140 | CD4: V151 | CE4: V152 | CF4: V155 | CG4: V157 | CH4: V158 | CI4: V190 | CJ4: V200 | CK4: V215 | CL4: V218 | CM4: V240 | CN4: V241 | CO4: V242 | CP4: V243 | CQ4: V251 | CR4: V252 | CS4: V253 | CT4: V254 | CU4: V255 | CV4: V256 | CW4: V257 | CX4: V258 | CY4: V259 | CZ4: V305 | DA4: V309 | DB4: V310 | DC4: V311 | DD4: V350 | DE4: V351 | DF4: V353 | DG4: V354 | DH4: V355 | DI4: V356 | DJ4: V357 | DK4: V358 | DL4: V359 | DM4: V360 | DN4: V362 | DO4: V363 | DP4: V365 | DQ4: V366 | DR4: V368 | DS4: V369 | DT4: V370 | DU4: V379 | DV4: V380 | DW4: V381 | DX4: V382 | DY4: V501 | DZ4: V502 | EA4: V503 | EB4: V504 | EC4: V505 | ED4: V506 | EE4: V507 | EF4: V508 | EG4: V509 | EH4: V510 | EI4: V511 | EJ4: V515 | EK4: V516 | EL4: V517 | EM4: V518 | EN4: V519 | EO4: V521 | EP4: V522 | EQ4: V523 | ER4: V524 | ES4: V525 | ET4: V526 | EU4: V528 | EV4: V529 | EW4: V531 | EX4: V532 | EY4: V533 | EZ4: V535 | FA4: V536 | FB4: V537 | FC4: V538 | FD4: V539 | FE4: V540 | FF4: V541 | FG4: V544 | FH4: V547 | FI4: V550 | FJ4: V551 | FK4: V552 | FL4: V553 | FM4: V554 | FN4: V555 | FO4: V556 | FP4: V557 | FQ4: V559 | FR4: V560 | FS4: V561 | FT4: V566 | FU4: V567 | FV4: V569 | FW4: V570 | FX4: V571 | FY4: V572 | FZ4: V574 | GA4: V584 | GB4: V590 | GC4: V591 | GD4: V592 | GE4: V593 | GF4: V594 | GG4: V595 | GH4: V596 | GI4: V597 | GJ4: V598 | GK4: V601 | GL4: V602 | GM4: V603 | GN4: V604 | GO4: V605 | GP4: V610 | GQ4: V701 | GR4: V702 | GS4: V711 | GT4: V712 | GU4: V750 | GV4: V801 | GW4: V900 | GX4: V904 | GY4: V905 | GZ4: V906 | HA4: V907 | HB4: V910 | HC4: V911 | HD4: V912 | HE4: V913 | HF4: V914 | HG4: V917 | HH4: V920 | HI4: V922
A5: PDC-D | B5: F200 | C5: Fusible | D5: N000000008708 | E5: 1012166 | F5: V1 | G5: 5A | H5: X
A6: PDC-D | B6: F201 | C6: Fusible | D6: N000000008709 | E6: 1012168 | F6: V523 | G6: 7.5A | EQ6: X
A7: PDC-D | B7: F202 | C7: Fusible | D7: N000000008710 | E7: 1012170 | F7: V590 | G7: 10A | GB7: X
A8: PDC-D | B8: F203 | C8: Fusible | D8: N000000008708 | E8: 1012166 | F8: V559 | G8: 5A | FQ8: X
A9: PDC-D | B9: F204 | C9: Fusible | D9: N000000008710 | E9: 1012170 | F9: V1 | G9: 10A | H9: X
A10: PDC-D | B10: F205 | C10: Fusible | D10: N000000008708 | E10: 1012166 | F10: V362/V363 | G10: 5A | DN10: X | DO10: X
A11: PDC-D | B11: F206 | C11: Fusible | D11: N000000008710 | E11: 1012170 | F11: V590 | G11: 10A | GB11: X
A12: PDC-D | B12: F207 | C12: Fusible | D12: N000000008710 | E12: 1012170 | F12: V157 | G12: 10A | CG12: X
A13: PDC-D | B13: F208 | C13: Fusible | D13: N000000008710 | E13: 1012170 | F13: V157 | G13: 10A | CG13: X
A14: PDC-D | B14: F209 | C14: Fusible | D14: N000000008704 | E14: 1012173 | F14: V1 | G14: 30A | H14: X
A15: PDC-D | B15: F210 | C15: Fusible | D15: N000000008708 | E15: 1012166 | F15: V255 | G15: 5A | CU15: X
A16: PDC-D | B16: F211 | C16: Fusible | D16: N000000008704 | E16: 1012173 | F16: V1 | G16: 30A | H16: X
A17: PDC-D | B17: F212 | C17: Fusible | D17: N000000008704 | E17: 1012173 | F17: V252 | G17: 30A | CR17: X
A18: PDC-D | B18: F213 | C18: Fusible | D18: N000000008708 | E18: 1012166 | F18: V1 | G18: 5A | H18: X
A19: PDC-D | B19: F214 | C19: Fusible | D19: N000000008704 | E19: 1012173 | F19: V1 | G19: 30A | H19: X
A20: PDC-D | B20: F215 | C20: Fusible | D20: N000000008704 | E20: 1012173 | F20: V1 | G20: 30A | H20: X
A21: PDC-D | B21: F216 | C21: Fusible | D21: N000000008703 | E21: 1012171 | F21: V1 | G21: 25A | H21: X
A22: PDC-D | B22: F217 | C22: Fusible | D22: N000000008711 | E22: 1012169 | F22: V1 | G22: 15A | H22: X
A23: PDC-D | B23: F219 | C23: Fusible | D23: N000000008710 | E23: 1012170 | F23: V1 | G23: 10A | H23: X
A24: PDC-D | B24: F220 | C24: Fusible | D24: N000000008708 | E24: 1012166 | F24: V1 | G24: 5A | H24: X
A25: PDC-D | B25: F221 | C25: Fusible | D25: N000000008711 | E25: 1012169 | F25: V1 | G25: 15A | H25: X
A26: PDC-D | B26: F222 | C26: Fusible | D26: N000000008710 | E26: 1012170 | F26: V1 | G26: 10A | H26: X
A27: PDC-D | B27: F223 | C27: Fusible | D27: N000000008709 | E27: 1012168 | F27: V610 | G27: 7.5A | GP27: X
A28: PDC-D | B28: F224 | C28: Fusible | D28: N000000008709 | E28: 1012168 | F28: V1 | G28: 7.5A | H28: X
A29: PDC-D | B29: F225 | C29: Fusible | D29: N000000008711 | E29: 1012169 | F29: V1 | G29: 15A | H29: X
A30: PDC-D | B30: F226 | C30: Fusible | D30: N000000008709 | E30: 1012168 | F30: V1 | G30: 7.5A | H30: X
A31: PDC-D | B31: F227 | C31: Fusible | D31: N000000008708 | E31: 1012166 | F31: V1 | G31: 5A | H31: X
A32: PDC-D | B32: F229 | C32: Fusible | D32: N000000008708 | E32: 1012166 | F32: V1 | G32: 5A | H32: X
A33: PDC-D | B33: F230 | C33: Fusible | D33: N000000008708 | E33: 1012166 | F33: V1 | G33: 5A | H33: X
A34: PDC-D | B34: F231 | C34: Fusible | D34: N000000008708 | E34: 1012166 | F34: V1 | G34: 5A | H34: X

Sheet Matriz Interior Izquierda PDC-R
A3: Fusibles | H3: =VLOOKUP(H4,'Acomodos Modularidades'!$A$2:$B$211,2,FALSE) -> A2965400909 | I3: =VLOOKUP(I4,'Acomodos Modularidades'!$A$2:$B$211,2,FALSE) -> A2965402613 | J3: =VLOOKUP(J4,'Acomodos Modularidades'!$A$2:$B$211,2,FALSE) -> A2965400008 | K3: =VLOOKUP(K4,'Acomodos Modularidades'!$A$2:$B$211,2,FALSE) -> A2965409911 | L3: =VLOOKUP(L4,'Acomodos Modularidades'!$A$2:$B$211,2,FALSE) -> A2965404500 | M3: =VLOOKUP(M4,'Acomodos Modularidades'!$A$2:$B$211,2,FALSE) -> A2965404700 | N3: =VLOOKUP(N4,'Acomodos Modularidades'!$A$2:$B$211,2,FALSE) -> A2965404900 | O3: =VLOOKUP(O4,'Acomodos Modularidades'!$A$2:$B$211,2,FALSE) -> A2965405100 | ... HI3: =VLOOKUP(HI4,'Acomodos Modularidades'!$A$2:$B$211,2,FALSE) -> A2965406419
A4: Subensamble | B4: kurzname | C4: Descripcion | D4: # Mercedez | E4: Oracle (s) | F4: Variante | G4: Amp | H4: V1 | I4: V2 | J4: V6 | K4: V8 | L4: V9 | M4: V10 | N4: V11 | O4: V12 | P4: V13 | Q4: V14 | R4: V15 | S4: V16 | T4: V17 | U4: V18 | V4: V19 | W4: V20 | X4: V23 | Y4: V26 | Z4: V29 | AA4: V30 | AB4: V31 | AC4: V32 | AD4: V33 | AE4: V34 | AF4: V38 | AG4: V41 | AH4: V42 | AI4: V43 | AJ4: V44 | AK4: V45 | AL4: V46 | AM4: V48 | AN4: V49 | AO4: V50 | AP4: V51 | AQ4: V60 | AR4: V62 | AS4: V63 | AT4: V65 | AU4: V68 | AV4: V69 | AW4: V70 | AX4: V71 | AY4: V73 | AZ4: V74 | BA4: V75 | BB4: V76 | BC4: V77 | BD4: V79 | BE4: V81 | BF4: V83 | BG4: V86 | BH4: V89 | BI4: V91 | BJ4: V93 | BK4: V94 | BL4: V96 | BM4: V97 | BN4: V100 | BO4: V102 | BP4: V103 | BQ4: V105 | BR4: V106 | BS4: V110 | BT4: V111 | BU4: V132 | BV4: V133 | BW4: V134 | BX4: V135 | BY4: V136 | BZ4: V137 | CA4: V138 | CB4: V139 | CC4: V140 | CD4: V151 | CE4: V152 | CF4: V155 | CG4: V157 | CH4: V158 | CI4: V190 | CJ4: V200 | CK4: V215 | CL4: V218 | CM4: V240 | CN4: V241 | CO4: V242 | CP4: V243 | CQ4: V251 | CR4: V252 | CS4: V253 | CT4: V254 | CU4: V255 | CV4: V256 | CW4: V257 | CX4: V258 | CY4: V259 | CZ4: V305 | DA4: V309 | DB4: V310 | DC4: V311 | DD4: V350 | DE4: V351 | DF4: V353 | DG4: V354 | DH4: V355 | DI4: V356 | DJ4: V357 | DK4: V358 | DL4: V359 | DM4: V360 | DN4: V362 | DO4: V363 | DP4: V365 | DQ4: V366 | DR4: V368 | DS4: V369 | DT4: V370 | DU4: V379 | DV4: V380 | DW4: V381 | DX4: V382 | DY4: V501 | DZ4: V502 | EA4: V503 | EB4: V504 | EC4: V505 | ED4: V506 | EE4: V507 | EF4: V508 | EG4: V509 | EH4: V510 | EI4: V511 | EJ4: V515 | EK4: V516 | EL4: V517 | EM4: V518 | EN4: V519 | EO4: V521 | EP4: V522 | EQ4: V523 | ER4: V524 | ES4: V525 | ET4: V526 | EU4: V528 | EV4: V529 | EW4: V531 | EX4: V532 | EY4: V533 | EZ4: V535 | FA4: V536 | FB4: V537 | FC4: V538 | FD4: V539 | FE4: V540 | FF4: V541 | FG4: V544 | FH4: V547 | FI4: V550 | FJ4: V551 | FK4: V552 | FL4: V553 | FM4: V554 | FN4: V555 | FO4: V556 | FP4: V557 | FQ4: V559 | FR4: V560 | FS4: V561 | FT4: V566 | FU4: V567 | FV4: V569 | FW4: V570 | FX4: V571 | FY4: V572 | FZ4: V574 | GA4: V584 | GB4: V590 | GC4: V591 | GD4: V592 | GE4: V593 | GF4: V594 | GG4: V595 | GH4: V596 | GI4: V597 | GJ4: V598 | GK4: V601 | GL4: V602 | GM4: V603 | GN4: V604 | GO4: V605 | GP4: V610 | GQ4: V701 | GR4: V702 | GS4: V711 | GT4: V712 | GU4: V750 | GV4: V801 | GW4: V900 | GX4: V904 | GY4: V905 | GZ4: V906 | HA4: V907 | HB4: V910 | HC4: V911 | HD4: V912 | HE4: V913 | HF4: V914 | HG4: V917 | HH4: V920 | HI4: V922
A5: PDC-R | B5: X | C5: Relay | D5: A0009821923 | E5: 1008695 | F5: V1 | G5: 60A | H5: X
A6: PDC-R | B6: F430 | C6: Fusible | D6: N000000008711 | E6: 1012169 | F6: V1 | G6: 15A | H6: X
A7: PDC-R | B7: F431 | C7: Fusible | D7: N000000008710 | E7: 1012170 | F7: V1 | G7: 10A | H7: X
A8: PDC-R | B8: F437 | C8: Fusible | D8: N000000008708 | E8: 1012166 | F8: V350 | G8: 5A | DD8: X
A9: PDC-R | B9: F438 | C9: Fusible | D9: N000000008709 | E9: 1012168 | F9: V569/V570 | G9: 7.5A | FV9: X | FW9: X
A10: PDC-R | B10: F439 | C10: Fusible | D10: N000000008711 | E10: 1012169 | F10: V711/V712 | G10: 15A | GS10: X | GT10: X
A11: PDC-R | B11: F440 | C11: Fusible | D11: N000000008709 | E11: 1012168 | F11: V524 | G11: 7.5A | ER11: X
A12: PDC-R | B12: F441 | C12: Fusible | D12: N000000008709 | E12: 1012168 | F12: V584 | G12: 7.5A | GA12: X
A13: PDC-R | B13: F411 | C13: Fusible | D13: N000000008708 | E13: 1012166 | F13: V358 | G13: 5A | DK13: X
A14: PDC-R | B14: F409 | C14: Fusible | D14: N000000008708 | E14: 1012166 | F14: V557 | G14: 5A | FP14: X
A15: PDC-R | B15: F450 | C15: Fusible | D15: N000000008704 | E15: 1012173 | F15: V215 | G15: 30A | CK15: X
A16: PDC-R | B16: F451 | C16: Fusible | D16: N000000008702 | E16: 1012167 | F16: V215 | G16: 20A | CK16: X
A17: PDC-R | B17: F452 | C17: Fusible | D17: N000000008703 | E17: 1012171 | F17: V215 | G17: 25A | CK17: X
A18: PDC-R | B18: F453 | C18: Fusible | D18: N000000008703 | E18: 1012171 | F18: V215 | G18: 25A | CK18: X
A19: PDC-R | B19: F454 | C19: Fusible | D19: N000000008704 | E19: 1012173 | F19: V133 | G19: 30A | BV19: X
A20: PDC-R | B20: F455 | C20: Fusible | D20: N000000008704 | E20: 1012173 | F20: V158 | G20: 30A | CH20: X
A21: PDC-R | B21: F447 | C21: Fusible | D21: N000000007659 | E21: 1012175 | F21: V900 | G21: 40A | GW21: X
A22: PDC-R | B22: F456 | C22: Fusible | D22: N000000008704 | E22: 1012173 | F22: V158 | G22: 30A | CH22: X
A23: PDC-R | B23: F457 | C23: Fusible | D23: N000000008703 | E23: 1012171 | F23: V544 | G23: 25A | FG23: X
A24: PDC-R | B24: F460 | C24: Fusible | D24: N000000008701 | E24: 1012172 | F24: V503 | G24: 15A | EA24: X
A25: PDC-R | B25: F461 | C25: Fusible | D25: N000000008704 | E25: 1012173 | F25: V190 | G25: 30A | CI25: X
A26: PDC-R | B26: T | C26: Relay | D26: A0025429419 | E26: 1010733 | F26: V1 | G26: 70A | H26: X
A27: PDC-R | B27: F432 | C27: Fusible | D27: N000000008709 | E27: 1012168 | F27: V1 | G27: 7.5A | H27: X
A28: PDC-R | B28: F436 | C28: Fusible | D28: N000000008710 | E28: 1012170 | F28: V574 | G28: 10A | FZ28: X
A29: PDC-R | B29: F442 | C29: Fusible | D29: N000000008708 | E29: 1012166 | F29: V561 | G29: 5A | FS29: X
A30: PDC-R | B30: F443 | C30: Fusible | D30: N000000008708 | E30: 1012166 | F30: V251 | G30: 5A | CQ30: X
A31: PDC-R | B31: F445 | C31: Fusible | D31: N000000008698 | E31: 1012177 | F31: V158 | G31: 5A | CH31: X
A32: PDC-R | B32: F446 | C32: Fusible | D32: N000000008708 | E32: 1012166 | F32: V360 | G32: 5A | DM32: X
A33: PDC-R | B33: F420 | C33: Fusible | D33: N000000007659 | E33: 1012175 | F33: V241 | G33: 40A | CN33: X
A34: PDC-R | B34: F419 | C34: Fusible | D34: N000000007659 | E34: 1012175 | F34: V49 | G34: 40A | AN34: X
A35: PDC-R | B35: F418 | C35: Fusible | D35: N000000007659 | E35: 1012175 | F35: V504 | G35: 40A | EB35: X
A36: PDC-R | B36: F413 | C36: Fusible | D36: N000000008704 | E36: 1012173 | F36: V1 | G36: 30A | H36: X
A37: PDC-R | B37: F414 | C37: Fusible | D37: N000000008704 | E37: 1012173 | F37: V152 | G37: 30A | CE37: X
A38: PDC-R | B38: F415 | C38: Fusible | D38: N000000008704 | E38: 1012173 | F38: V1 | G38: 30A | H38: X
A39: PDC-R | B39: F416 | C39: Fusible | D39: N000000008704 | E39: 1012173 | F39: V74/V75 | G39: 30A | AZ39: X | BA39: X
A40: PDC-R | B40: F417 | C40: Fusible | D40: N000000008704 | E40: 1012173 | F40: V74/V75 | G40: 30A | AZ40: X | BA40: X
A41: PDC-R | B41: F402 | C41: Fusible | D41: N000000008703 | E41: 1012171 | F41: V140 | G41: 25A | CC41: X
A42: PDC-R | B42: F421 | C42: Fusible | D42: N000000008704 | E42: 1012173 | F42: V1 | G42: 30A | H42: X
...

Sheet Matriz Interior Izquierda PDC-P
A3: Fusibles | H3: =VLOOKUP(H4,'Acomodos Modularidades'!$A$2:$B$211,2,FALSE) -> A2965400909 | I3: =VLOOKUP(I4,'Acomodos Modularidades'!$A$2:$B$211,2,FALSE) -> A2965402613 | J3: =VLOOKUP(J4,'Acomodos Modularidades'!$A$2:$B$211,2,FALSE) -> A2965400008 | K3: =VLOOKUP(K4,'Acomodos Modularidades'!$A$2:$B$211,2,FALSE) -> A2965409911 | L3: =VLOOKUP(L4,'Acomodos Modularidades'!$A$2:$B$211,2,FALSE) -> A2965404500 | M3: =VLOOKUP(M4,'Acomodos Modularidades'!$A$2:$B$211,2,FALSE) -> A2965404700 | N3: =VLOOKUP(N4,'Acomodos Modularidades'!$A$2:$B$211,2,FALSE) -> A2965404900 | O3: =VLOOKUP(O4,'Acomodos Modularidades'!$A$2:$B$211,2,FALSE) -> A2965405100 | ... HI3: =VLOOKUP(HI4,'Acomodos Modularidades'!$A$2:$B$211,2,FALSE) -> A2965406419
A4: Subensamble | B4: kurzname | C4: Descripcion | D4: # Mercedez | E4: Oracle (s) | F4: Variante | G4: Amp | H4: V1 | I4: V2 | J4: V6 | K4: V8 | L4: V9 | M4: V10 | N4: V11 | O4: V12 | P4: V13 | Q4: V14 | R4: V15 | S4: V16 | T4: V17 | U4: V18 | V4: V19 | W4: V20 | X4: V23 | Y4: V26 | Z4: V29 | AA4: V30 | AB4: V31 | AC4: V32 | AD4: V33 | AE4: V34 | AF4: V38 | AG4: V41 | AH4: V42 | AI4: V43 | AJ4: V44 | AK4: V45 | AL4: V46 | AM4: V48 | AN4: V49 | AO4: V50 | AP4: V51 | AQ4: V60 | AR4: V62 | AS4: V63 | AT4: V65 | AU4: V68 | AV4: V69 | AW4: V70 | AX4: V71 | AY4: V73 | AZ4: V74 | BA4: V75 | BB4: V76 | BC4: V77 | BD4: V79 | BE4: V81 | BF4: V83 | BG4: V86 | BH4: V89 | BI4: V91 | BJ4: V93 | BK4: V94 | BL4: V96 | BM4: V97 | BN4: V100 | BO4: V102 | BP4: V103 | BQ4: V105 | BR4: V106 | BS4: V110 | BT4: V111 | BU4: V132 | BV4: V133 | BW4: V134 | BX4: V135 | BY4: V136 | BZ4: V137 | CA4: V138 | CB4: V139 | CC4: V140 | CD4: V151 | CE4: V152 | CF4: V155 | CG4: V157 | CH4: V158 | CI4: V190 | CJ4: V200 | CK4: V215 | CL4: V218 | CM4: V240 | CN4: V241 | CO4: V242 | CP4: V243 | CQ4: V251 | CR4: V252 | CS4: V253 | CT4: V254 | CU4: V255 | CV4: V256 | CW4: V257 | CX4: V258 | CY4: V259 | CZ4: V305 | DA4: V309 | DB4: V310 | DC4: V311 | DD4: V350 | DE4: V351 | DF4: V353 | DG4: V354 | DH4: V355 | DI4: V356 | DJ4: V357 | DK4: V358 | DL4: V359 | DM4: V360 | DN4: V362 | DO4: V363 | DP4: V365 | DQ4: V366 | DR4: V368 | DS4: V369 | DT4: V370 | DU4: V379 | DV4: V380 | DW4: V381 | DX4: V382 | DY4: V501 | DZ4: V502 | EA4: V503 | EB4: V504 | EC4: V505 | ED4: V506 | EE4: V507 | EF4: V508 | EG4: V509 | EH4: V510 | EI4: V511 | EJ4: V515 | EK4: V516 | EL4: V517 | EM4: V518 | EN4: V519 | EO4: V521 | EP4: V522 | EQ4: V523 | ER4: V524 | ES4: V525 | ET4: V526 | EU4: V528 | EV4: V529 | EW4: V531 | EX4: V532 | EY4: V533 | EZ4: V535 | FA4: V536 | FB4: V537 | FC4: V538 | FD4: V539 | FE4: V540 | FF4: V541 | FG4: V544 | FH4: V547 | FI4: V550 | FJ4: V551 | FK4: V552 | FL4: V553 | FM4: V554 | FN4: V555 | FO4: V556 | FP4: V557 | FQ4: V559 | FR4: V560 | FS4: V561 | FT4: V566 | FU4: V567 | FV4: V569 | FW4: V570 | FX4: V571 | FY4: V572 | FZ4: V574 | GA4: V584 | GB4: V590 | GC4: V591 | GD4: V592 | GE4: V593 | GF4: V594 | GG4: V595 | GH4: V596 | GI4: V597 | GJ4: V598 | GK4: V601 | GL4: V602 | GM4: V603 | GN4: V604 | GO4: V605 | GP4: V610 | GQ4: V701 | GR4: V702 | GS4: V711 | GT4: V712 | GU4: V750 | GV4: V801 | GW4: V900 | GX4: V904 | GY4: V905 | GZ4: V906 | HA4: V907 | HB4: V910 | HC4: V911 | HD4: V912 | HE4: V913 | HF4: V914 | HG4: V917 | HH4: V920 | HI4: V922
A5: PDC-P | B5: F300 | C5: Fusible | D5: N000000008701 | E5: 1012172 | F5: V1 | G5: 15A | H5: X
A6: PDC-P | B6: F302 | C6: Fusible | D6: N000000008708 | E6: 1012166 | F6: V50 | G6: 5A | AO6: X
A7: PDC-P | B7: F303 | C7: Fusible | D7: N000000008708 | E7: 1012166 | F7: V50 | G7: 5A | AO7: X
A8: PDC-P | B8: F304 | C8: Fusible | D8: N000000008708 | E8: 1012166 | F8: V541 | G8: 5A | FF8: X
A9: PDC-P | B9: F318 | C9: Fusible | D9: N000000008709 | E9: 1012168 | F9: V60 | G9: 7.5A | AQ9: X
A10: PDC-P | B10: F319 | C10: Fusible | D10: N000000008709 | E10: 1012168 | F10: V521 | G10: 7.5A | EO10: X
A11: PDC-P | B11: F320 | C11: Fusible | D11: N000000008709 | E11: 1012168 | F11: V1 | G11: 7.5A | H11: X
A12: PDC-P | B12: F321 | C12: Fusible | D12: N000000008709 | E12: 1012168 | F12: V801 | G12: 7.5A | GV12: X
A13: PDC-P | B13: F322 | C13: Fusible | D13: N000000008709 | E13: 1012168 | F13: V1 | G13: 7.5A | H13: X
A14: PDC-P | B14: F323 | C14: Fusible | D14: N000000008709 | E14: 1012168 | F14: V357/V358 | G14: 7.5A | DJ14: X | DK14: X
A15: PDC-P | B15: F326 | C15: Fusible | D15: N000000008704 | E15: 1012173 | F15: V1 | G15: 30A | H15: X
A16: PDC-P | B16: F327 | C16: Fusible | D16: N000000008704 | E16: 1012173 | F16: V501 | G16: 30A | DY16: X
A17: PDC-P | B17: F328 | C17: Fusible | D17: N000000008704 | E17: 1012173 | F17: V151 | G17: 30A | CD17: X
A18: PDC-P | B18: F329 | C18: Fusible | D18: N000000008704 | E18: 1012173 | F18: V151 | G18: 30A | CD18: X
A19: PDC-P | B19: F330 | C19: Fusible | D19: N000000008704 | E19: 1012173 | F19: V152 | G19: 30A | CE19: X
A20: PDC-P | B20: F331 | C20: Fusible | D20: N000000008704 | E20: 1012173 | F20: V252 | G20: 30A | CR20: X
A21: PDC-P | B21: F332 | C21: Fusible | D21: N000000008701 | E21: 1012172 | F21: V1 | G21: 15A | H21: X
A22: PDC-P | B22: F333 | C22: Fusible | D22: N000000008704 | E22: 1012173 | F22: V200 | G22: 30A | CJ22: X
A23: PDC-P | B23: F334 | C23: Fusible | D23: N000000008704 | E23: 1012173 | F23: V200 | G23: 30A | CJ23: X
A24: PDC-P | B24: F335 | C24: Fusible | D24: N000000008703 | E24: 1012171 | F24: V1 | G24: 25A | H24: X
A25: PDC-P | B25: F301 | C25: Fusible | D25: N000000008711 | E25: 1012169 | F25: V900 | G25: 15A | GW25: X
A26: PDC-P | B26: MF1 | C26: Multifuse | D26: N000000006466 | E26: 1012146 | F26: V103/ V155 | G26: 7.5A | BP26: X | CF26: X
A27: PDC-P | B27: MF2 | C27: Multifuse | D27: N000000006465 | E27: 1012147 | F27: V362/ V363 | G27: 5A | DN27: X | DO27: X

Sheet Matriz Interior Izquierda F55
A3: Fusibles | H3: =VLOOKUP(H4,'Acomodos Modularidades'!$A$2:$B$211,2,FALSE) -> A2965400909 | I3: =VLOOKUP(I4,'Acomodos Modularidades'!$A$2:$B$211,2,FALSE) -> A2965402613 | J3: =VLOOKUP(J4,'Acomodos Modularidades'!$A$2:$B$211,2,FALSE) -> A2965400008 | K3: =VLOOKUP(K4,'Acomodos Modularidades'!$A$2:$B$211,2,FALSE) -> A2965409911 | L3: =VLOOKUP(L4,'Acomodos Modularidades'!$A$2:$B$211,2,FALSE) -> A2965404500 | M3: =VLOOKUP(M4,'Acomodos Modularidades'!$A$2:$B$211,2,FALSE) -> A2965404700 | N3: =VLOOKUP(N4,'Acomodos Modularidades'!$A$2:$B$211,2,FALSE) -> A2965404900 | O3: =VLOOKUP(O4,'Acomodos Modularidades'!$A$2:$B$211,2,FALSE) -> A2965405100 | ... HI3: =VLOOKUP(HI4,'Acomodos Modularidades'!$A$2:$B$211,2,FALSE) -> A2965406419
A4: Subensamble | B4: kurzname | C4: Descripcion | D4: # Mercedez | E4: Oracle (s) | F4: Variante | G4: Amp | H4: V1 | I4: V2 | J4: V6 | K4: V8 | L4: V9 | M4: V10 | N4: V11 | O4: V12 | P4: V13 | Q4: V14 | R4: V15 | S4: V16 | T4: V17 | U4: V18 | V4: V19 | W4: V20 | X4: V23 | Y4: V26 | Z4: V29 | AA4: V30 | AB4: V31 | AC4: V32 | AD4: V33 | AE4: V34 | AF4: V38 | AG4: V41 | AH4: V42 | AI4: V43 | AJ4: V44 | AK4: V45 | AL4: V46 | AM4: V48 | AN4: V49 | AO4: V50 | AP4: V51 | AQ4: V60 | AR4: V62 | AS4: V63 | AT4: V65 | AU4: V68 | AV4: V69 | AW4: V70 | AX4: V71 | AY4: V73 | AZ4: V74 | BA4: V75 | BB4: V76 | BC4: V77 | BD4: V79 | BE4: V81 | BF4: V83 | BG4: V86 | BH4: V89 | BI4: V91 | BJ4: V93 | BK4: V94 | BL4: V96 | BM4: V97 | BN4: V100 | BO4: V102 | BP4: V103 | BQ4: V105 | BR4: V106 | BS4: V110 | BT4: V111 | BU4: V132 | BV4: V133 | BW4: V134 | BX4: V135 | BY4: V136 | BZ4: V137 | CA4: V138 | CB4: V139 | CC4: V140 | CD4: V151 | CE4: V152 | CF4: V155 | CG4: V157 | CH4: V158 | CI4: V190 | CJ4: V200 | CK4: V215 | CL4: V218 | CM4: V240 | CN4: V241 | CO4: V242 | CP4: V243 | CQ4: V251 | CR4: V252 | CS4: V253 | CT4: V254 | CU4: V255 | CV4: V256 | CW4: V257 | CX4: V258 | CY4: V259 | CZ4: V305 | DA4: V309 | DB4: V310 | DC4: V311 | DD4: V350 | DE4: V351 | DF4: V353 | DG4: V354 | DH4: V355 | DI4: V356 | DJ4: V357 | DK4: V358 | DL4: V359 | DM4: V360 | DN4: V362 | DO4: V363 | DP4: V365 | DQ4: V366 | DR4: V368 | DS4: V369 | DT4: V370 | DU4: V379 | DV4: V380 | DW4: V381 | DX4: V382 | DY4: V501 | DZ4: V502 | EA4: V503 | EB4: V504 | EC4: V505 | ED4: V506 | EE4: V507 | EF4: V508 | EG4: V509 | EH4: V510 | EI4: V511 | EJ4: V515 | EK4: V516 | EL4: V517 | EM4: V518 | EN4: V519 | EO4: V521 | EP4: V522 | EQ4: V523 | ER4: V524 | ES4: V525 | ET4: V526 | EU4: V528 | EV4: V529 | EW4: V531 | EX4: V532 | EY4: V533 | EZ4: V535 | FA4: V536 | FB4: V537 | FC4: V538 | FD4: V539 | FE4: V540 | FF4: V541 | FG4: V544 | FH4: V547 | FI4: V550 | FJ4: V551 | FK4: V552 | FL4: V553 | FM4: V554 | FN4: V555 | FO4: V556 | FP4: V557 | FQ4: V559 | FR4: V560 | FS4: V561 | FT4: V566 | FU4: V567 | FV4: V569 | FW4: V570 | FX4: V571 | FY4: V572 | FZ4: V574 | GA4: V584 | GB4: V590 | GC4: V591 | GD4: V592 | GE4: V593 | GF4: V594 | GG4: V595 | GH4: V596 | GI4: V597 | GJ4: V598 | GK4: V601 | GL4: V602 | GM4: V603 | GN4: V604 | GO4: V605 | GP4: V610 | GQ4: V701 | GR4: V702 | GS4: V711 | GT4: V712 | GU4: V750 | GV4: V801 | GW4: V900 | GX4: V904 | GY4: V905 | GZ4: V906 | HA4: V907 | HB4: V910 | HC4: V911 | HD4: V912 | HE4: V913 | HF4: V914 | HG4: V917 | HH4: V920 | HI4: V922
A5: Fuse Box F55 | B5: 1A | C5: Fusible | D5: N000000004204 | E5: 1012179 | F5: V900 | G5: 10A | GW5: X
A6: Fuse Box F55 | B6: 2A | C6: Fusible | D6: N000000004202 | E6: 1012180 | F6: V900 | G6: 5A | GW6: X
A7: Fuse Box F55 | B7: 3A | C7: Fusible | D7: N000000004204 | E7: 1012179 | F7: V900 | G7: 10A | GW7: X
A8: Fuse Box F55 | B8: 4A | C8: Fusible | D8: N000000004204 | E8: 1012179 | F8: V900 | G8: 10A | GW8: X
A9: Fuse Box F55 | B9: 5A | C9: Fusible | D9: N000000004204 | E9: 1012179 | F9: V900 | G9: 10A | GW9: X
A10: Fuse Box F55 | B10: 7A | C10: Fusible | D10: N000000004202 | E10: 1012180 | F10: V900 | G10: 5A | GW10: X

Sheet MFB-P1
A3: Fusibles | I3: =VLOOKUP(I4,'Acomodos Modularidades'!$A$2:$B$211,2,FALSE) -> A2965400909 | J3: =VLOOKUP(J4,'Acomodos Modularidades'!$A$2:$B$211,2,FALSE) -> A2965402613 | K3: =VLOOKUP(K4,'Acomodos Modularidades'!$A$2:$B$211,2,FALSE) -> A2965400008 | L3: =VLOOKUP(L4,'Acomodos Modularidades'!$A$2:$B$211,2,FALSE) -> A2965409911 | M3: =VLOOKUP(M4,'Acomodos Modularidades'!$A$2:$B$211,2,FALSE) -> A2965404500 | N3: =VLOOKUP(N4,'Acomodos Modularidades'!$A$2:$B$211,2,FALSE) -> A2965404700 | O3: =VLOOKUP(O4,'Acomodos Modularidades'!$A$2:$B$211,2,FALSE) -> A2965404900 | P3: =VLOOKUP(P4,'Acomodos Modularidades'!$A$2:$B$211,2,FALSE) -> A2965405100 | ... HJ3: =VLOOKUP(HJ4,'Acomodos Modularidades'!$A$2:$B$211,2,FALSE) -> A2965406419
A4: Subensamble | B4: Slot | C4: Descripcion | D4: Kurzname | E4: Oracle Terminal | F4: Oracle Tuerca | G4: Variante | H4: Amp | I4: V1 | J4: V2 | K4: V6 | L4: V8 | M4: V9 | N4: V10 | O4: V11 | P4: V12 | Q4: V13 | R4: V14 | S4: V15 | T4: V16 | U4: V17 | V4: V18 | W4: V19 | X4: V20 | Y4: V23 | Z4: V26 | AA4: V29 | AB4: V30 | AC4: V31 | AD4: V32 | AE4: V33 | AF4: V34 | AG4: V38 | AH4: V41 | AI4: V42 | AJ4: V43 | AK4: V44 | AL4: V45 | AM4: V46 | AN4: V48 | AO4: V49 | AP4: V50 | AQ4: V51 | AR4: V60 | AS4: V62 | AT4: V63 | AU4: V65 | AV4: V68 | AW4: V69 | AX4: V70 | AY4: V71 | AZ4: V73 | BA4: V74 | BB4: V75 | BC4: V76 | BD4: V77 | BE4: V79 | BF4: V81 | BG4: V83 | BH4: V86 | BI4: V89 | BJ4: V91 | BK4: V93 | BL4: V94 | BM4: V96 | BN4: V97 | BO4: V100 | BP4: V102 | BQ4: V103 | BR4: V105 | BS4: V106 | BT4: V110 | BU4: V111 | BV4: V132 | BW4: V133 | BX4: V134 | BY4: V135 | BZ4: V136 | CA4: V137 | CB4: V138 | CC4: V139 | CD4: V140 | CE4: V151 | CF4: V152 | CG4: V155 | CH4: V157 | CI4: V158 | CJ4: V190 | CK4: V200 | CL4: V215 | CM4: V218 | CN4: V240 | CO4: V241 | CP4: V242 | CQ4: V243 | CR4: V251 | CS4: V252 | CT4: V253 | CU4: V254 | CV4: V255 | CW4: V256 | CX4: V257 | CY4: V258 | CZ4: V259 | DA4: V305 | DB4: V309 | DC4: V310 | DD4: V311 | DE4: V350 | DF4: V351 | DG4: V353 | DH4: V354 | DI4: V355 | DJ4: V356 | DK4: V357 | DL4: V358 | DM4: V359 | DN4: V360 | DO4: V362 | DP4: V363 | DQ4: V365 | DR4: V366 | DS4: V368 | DT4: V369 | DU4: V370 | DV4: V379 | DW4: V380 | DX4: V381 | DY4: V382 | DZ4: V501 | EA4: V502 | EB4: V503 | EC4: V504 | ED4: V505 | EE4: V506 | EF4: V507 | EG4: V508 | EH4: V509 | EI4: V510 | EJ4: V511 | EK4: V515 | EL4: V516 | EM4: V517 | EN4: V518 | EO4: V519 | EP4: V521 | EQ4: V522 | ER4: V523 | ES4: V524 | ET4: V525 | EU4: V526 | EV4: V528 | EW4: V529 | EX4: V531 | EY4: V532 | EZ4: V533 | FA4: V535 | FB4: V536 | FC4: V537 | FD4: V538 | FE4: V539 | FF4: V540 | FG4: V541 | FH4: V544 | FI4: V547 | FJ4: V550 | FK4: V551 | FL4: V552 | FM4: V553 | FN4: V554 | FO4: V555 | FP4: V556 | FQ4: V557 | FR4: V559 | FS4: V560 | FT4: V561 | FU4: V566 | FV4: V567 | FW4: V569 | FX4: V570 | FY4: V571 | FZ4: V572 | GA4: V574 | GB4: V584 | GC4: V590 | GD4: V591 | GE4: V592 | GF4: V593 | GG4: V594 | GH4: V595 | GI4: V596 | GJ4: V597 | GK4: V598 | GL4: V601 | GM4: V602 | GN4: V603 | GO4: V604 | GP4: V605 | GQ4: V610 | GR4: V701 | GS4: V702 | GT4: V711 | GU4: V712 | GV4: V750 | GW4: V801 | GX4: V900 | GY4: V904 | GZ4: V905 | HA4: V906 | HB4: V907 | HC4: V910 | HD4: V911 | HE4: V912 | HF4: V913 | HG4: V914 | HH4: V917 | HI4: V920 | HJ4: V922
A5: MFB-P1 | B5: A41 | C5: Torque | D5: F150/6*A41-K | E5: 1008205 | F5: 1013224 | G5: V49 | AO5: X
A6: MFB-P1 | B6: A42 | C6: Torque | D6: F150/6*A42-K | E6: 1008215 | F6: 1013225 | G6: V49 | AO6: X
A7: MFB-P1 | B7: A43 | C7: Torque | D7: F150/6*A43-K | E7: 1008212 | F7: 1013225 | G7: V49 | AO7: X
A8: MFB-P1 | B8: A44 | C8: Torque | D8: F150/6*A44-K | E8: - | F8: 1013225 | G8: -
A9: MFB-P1 | B9: A45 | C9: Torque | D9: F150/6*A45-K | E9: 1008213 | F9: 1013225 | G9: V218 | CM9: X
A10: MFB-P1 | B10: A46 | C10: Torque | D10: F150/6*A46-K | E10: 1008223 | F10: 1013224 | G10: V49 | AO10: X
A11: MFB-P1 | B11: A47 | C11: Torque | D11: F150/6*A47-K | E11: - | F11: 1013224 | G11: -

Sheet MFB-P2
A3: Fusibles | I3: =VLOOKUP(I4,'Acomodos Modularidades'!$A$2:$B$211,2,FALSE) -> A2965400909 | J3: =VLOOKUP(J4,'Acomodos Modularidades'!$A$2:$B$211,2,FALSE) -> A2965402613 | K3: =VLOOKUP(K4,'Acomodos Modularidades'!$A$2:$B$211,2,FALSE) -> A2965400008 | L3: =VLOOKUP(L4,'Acomodos Modularidades'!$A$2:$B$211,2,FALSE) -> A2965409911 | M3: =VLOOKUP(M4,'Acomodos Modularidades'!$A$2:$B$211,2,FALSE) -> A2965404500 | N3: =VLOOKUP(N4,'Acomodos Modularidades'!$A$2:$B$211,2,FALSE) -> A2965404700 | O3: =VLOOKUP(O4,'Acomodos Modularidades'!$A$2:$B$211,2,FALSE) -> A2965404900 | P3: =VLOOKUP(P4,'Acomodos Modularidades'!$A$2:$B$211,2,FALSE) -> A2965405100 | ... HJ3: =VLOOKUP(HJ4,'Acomodos Modularidades'!$A$2:$B$211,2,FALSE) -> A2965406419
A4: Subensamble | B4: Slot | C4: Descripcion | D4: kurzname | E4: Oracle Terminal | F4: Oracle Tuerca | G4: Variante | H4: Amp | I4: V1 | J4: V2 | K4: V6 | L4: V8 | M4: V9 | N4: V10 | O4: V11 | P4: V12 | Q4: V13 | R4: V14 | S4: V15 | T4: V16 | U4: V17 | V4: V18 | W4: V19 | X4: V20 | Y4: V23 | Z4: V26 | AA4: V29 | AB4: V30 | AC4: V31 | AD4: V32 | AE4: V33 | AF4: V34 | AG4: V38 | AH4: V41 | AI4: V42 | AJ4: V43 | AK4: V44 | AL4: V45 | AM4: V46 | AN4: V48 | AO4: V49 | AP4: V50 | AQ4: V51 | AR4: V60 | AS4: V62 | AT4: V63 | AU4: V65 | AV4: V68 | AW4: V69 | AX4: V70 | AY4: V71 | AZ4: V73 | BA4: V74 | BB4: V75 | BC4: V76 | BD4: V77 | BE4: V79 | BF4: V81 | BG4: V83 | BH4: V86 | BI4: V89 | BJ4: V91 | BK4: V93 | BL4: V94 | BM4: V96 | BN4: V97 | BO4: V100 | BP4: V102 | BQ4: V103 | BR4: V105 | BS4: V106 | BT4: V110 | BU4: V111 | BV4: V132 | BW4: V133 | BX4: V134 | BY4: V135 | BZ4: V136 | CA4: V137 | CB4: V138 | CC4: V139 | CD4: V140 | CE4: V151 | CF4: V152 | CG4: V155 | CH4: V157 | CI4: V158 | CJ4: V190 | CK4: V200 | CL4: V215 | CM4: V218 | CN4: V240 | CO4: V241 | CP4: V242 | CQ4: V243 | CR4: V251 | CS4: V252 | CT4: V253 | CU4: V254 | CV4: V255 | CW4: V256 | CX4: V257 | CY4: V258 | CZ4: V259 | DA4: V305 | DB4: V309 | DC4: V310 | DD4: V311 | DE4: V350 | DF4: V351 | DG4: V353 | DH4: V354 | DI4: V355 | DJ4: V356 | DK4: V357 | DL4: V358 | DM4: V359 | DN4: V360 | DO4: V362 | DP4: V363 | DQ4: V365 | DR4: V366 | DS4: V368 | DT4: V369 | DU4: V370 | DV4: V379 | DW4: V380 | DX4: V381 | DY4: V382 | DZ4: V501 | EA4: V502 | EB4: V503 | EC4: V504 | ED4: V505 | EE4: V506 | EF4: V507 | EG4: V508 | EH4: V509 | EI4: V510 | EJ4: V511 | EK4: V515 | EL4: V516 | EM4: V517 | EN4: V518 | EO4: V519 | EP4: V521 | EQ4: V522 | ER4: V523 | ES4: V524 | ET4: V525 | EU4: V526 | EV4: V528 | EW4: V529 | EX4: V531 | EY4: V532 | EZ4: V533 | FA4: V535 | FB4: V536 | FC4: V537 | FD4: V538 | FE4: V539 | FF4: V540 | FG4: V541 | FH4: V544 | FI4: V547 | FJ4: V550 | FK4: V551 | FL4: V552 | FM4: V553 | FN4: V554 | FO4: V555 | FP4: V556 | FQ4: V557 | FR4: V559 | FS4: V560 | FT4: V561 | FU4: V566 | FV4: V567 | FW4: V569 | FX4: V570 | FY4: V571 | FZ4: V572 | GA4: V574 | GB4: V584 | GC4: V590 | GD4: V591 | GE4: V592 | GF4: V593 | GG4: V594 | GH4: V595 | GI4: V596 | GJ4: V597 | GK4: V598 | GL4: V601 | GM4: V602 | GN4: V603 | GO4: V604 | GP4: V605 | GQ4: V610 | GR4: V701 | GS4: V702 | GT4: V711 | GU4: V712 | GV4: V750 | GW4: V801 | GX4: V900 | GY4: V904 | GZ4: V905 | HA4: V906 | HB4: V907 | HC4: V910 | HD4: V911 | HE4: V912 | HF4: V913 | HG4: V914 | HH4: V917 | HI4: V920 | HJ4: V922
A5: MFB-P2 | B5: A20 | C5: Torque | D5: F150/7*A20-K | E5: 1008205 | F5: 1013224 | G5: V49 | AO5: X
A6: MFB-P2 | B6: A21 | C6: Torque | D6: F150/7*A21-K | E6: 1008216 | F6: 1013225 | G6: V49 | AO6: X
A7: MFB-P2 | B7: A22 | C7: Torque | D7: F150/7*A22-K | E7: 1008218 | F7: 1013225 | G7: V1 | I7: X
A8: MFB-P2 | B8: A23 | C8: Torque | D8: F150/7*A23-K | E8: 1008210 | F8: 1013225 | G8: V305 | DA8: X
A9: MFB-P2 | B9: A24 | C9: Torque | D9: F150/7*A24-K | E9: 1008211 | F9: 1013225 | G9: V49 | AO9: X
A10: MFB-P2 | B10: A25 | C10: Torque | D10: F150/7*A25-K | E10: 1008221 | F10: 1013224 | G10: V49 | AO10: X
A11: MFB-P2 | B11: A26 | C11: Torque | D11: F150/7*A26-K | E11: 1008215 | F11: 1013225 | G11: V311 | DD11: X
A12: MFB-P2 | B12: A27 | C12: Torque | D12: F150/7*A27-K | E12: 1008212 | F12: 1013225 | G12: V365
A13: MFB-P2 | B13: A28 | C13: Torque | D13: F150/7*A28-K | E13: 1008421 | F13: 1013225 | G13: V900 | GX13: X
A14: MFB-P2 | B14: A29 | C14: Torque | D14: F150/7*A29-K | E14: 1008448 | F14: 1013225 | G14: V311 | DD14: X
A15: MFB-P2 | B15: A30 | C15: Torque | D15: F150/7*A30-K | E15: 1008222 | F15: 1013224 | G15: V49 | AO15: X

Sheet MFB-S
A3: Fusibles | I3: =VLOOKUP(I4,'Acomodos Modularidades'!$A$2:$B$211,2,FALSE) -> A2965400909 | J3: =VLOOKUP(J4,'Acomodos Modularidades'!$A$2:$B$211,2,FALSE) -> A2965402613 | K3: =VLOOKUP(K4,'Acomodos Modularidades'!$A$2:$B$211,2,FALSE) -> A2965400008 | L3: =VLOOKUP(L4,'Acomodos Modularidades'!$A$2:$B$211,2,FALSE) -> A2965409911 | M3: =VLOOKUP(M4,'Acomodos Modularidades'!$A$2:$B$211,2,FALSE) -> A2965404500 | N3: =VLOOKUP(N4,'Acomodos Modularidades'!$A$2:$B$211,2,FALSE) -> A2965404700 | O3: =VLOOKUP(O4,'Acomodos Modularidades'!$A$2:$B$211,2,FALSE) -> A2965404900 | P3: =VLOOKUP(P4,'Acomodos Modularidades'!$A$2:$B$211,2,FALSE) -> A2965405100 | ... HJ3: =VLOOKUP(HJ4,'Acomodos Modularidades'!$A$2:$B$211,2,FALSE) -> A2965406419
A4: Subensamble | B4: Slot | C4: Descripcion | D4: Kurzname | E4: # Mercedez | F4: Oracle (s) | G4: Variante | H4: Amp | I4: V1 | J4: V2 | K4: V6 | L4: V8 | M4: V9 | N4: V10 | O4: V11 | P4: V12 | Q4: V13 | R4: V14 | S4: V15 | T4: V16 | U4: V17 | V4: V18 | W4: V19 | X4: V20 | Y4: V23 | Z4: V26 | AA4: V29 | AB4: V30 | AC4: V31 | AD4: V32 | AE4: V33 | AF4: V34 | AG4: V38 | AH4: V41 | AI4: V42 | AJ4: V43 | AK4: V44 | AL4: V45 | AM4: V46 | AN4: V48 | AO4: V49 | AP4: V50 | AQ4: V51 | AR4: V60 | AS4: V62 | AT4: V63 | AU4: V65 | AV4: V68 | AW4: V69 | AX4: V70 | AY4: V71 | AZ4: V73 | BA4: V74 | BB4: V75 | BC4: V76 | BD4: V77 | BE4: V79 | BF4: V81 | BG4: V83 | BH4: V86 | BI4: V89 | BJ4: V91 | BK4: V93 | BL4: V94 | BM4: V96 | BN4: V97 | BO4: V100 | BP4: V102 | BQ4: V103 | BR4: V105 | BS4: V106 | BT4: V110 | BU4: V111 | BV4: V132 | BW4: V133 | BX4: V134 | BY4: V135 | BZ4: V136 | CA4: V137 | CB4: V138 | CC4: V139 | CD4: V140 | CE4: V151 | CF4: V152 | CG4: V155 | CH4: V157 | CI4: V158 | CJ4: V190 | CK4: V200 | CL4: V215 | CM4: V218 | CN4: V240 | CO4: V241 | CP4: V242 | CQ4: V243 | CR4: V251 | CS4: V252 | CT4: V253 | CU4: V254 | CV4: V255 | CW4: V256 | CX4: V257 | CY4: V258 | CZ4: V259 | DA4: V305 | DB4: V309 | DC4: V310 | DD4: V311 | DE4: V350 | DF4: V351 | DG4: V353 | DH4: V354 | DI4: V355 | DJ4: V356 | DK4: V357 | DL4: V358 | DM4: V359 | DN4: V360 | DO4: V362 | DP4: V363 | DQ4: V365 | DR4: V366 | DS4: V368 | DT4: V369 | DU4: V370 | DV4: V379 | DW4: V380 | DX4: V381 | DY4: V382 | DZ4: V501 | EA4: V502 | EB4: V503 | EC4: V504 | ED4: V505 | EE4: V506 | EF4: V507 | EG4: V508 | EH4: V509 | EI4: V510 | EJ4: V511 | EK4: V515 | EL4: V516 | EM4: V517 | EN4: V518 | EO4: V519 | EP4: V521 | EQ4: V522 | ER4: V523 | ES4: V524 | ET4: V525 | EU4: V526 | EV4: V528 | EW4: V529 | EX4: V531 | EY4: V532 | EZ4: V533 | FA4: V535 | FB4: V536 | FC4: V537 | FD4: V538 | FE4: V539 | FF4: V540 | FG4: V541 | FH4: V544 | FI4: V547 | FJ4: V550 | FK4: V551 | FL4: V552 | FM4: V553 | FN4: V554 | FO4: V555 | FP4: V556 | FQ4: V557 | FR4: V559 | FS4: V560 | FT4: V561 | FU4: V566 | FV4: V567 | FW4: V569 | FX4: V570 | FY4: V571 | FZ4: V572 | GA4: V574 | GB4: V584 | GC4: V590 | GD4: V591 | GE4: V592 | GF4: V593 | GG4: V594 | GH4: V595 | GI4: V596 | GJ4: V597 | GK4: V598 | GL4: V601 | GM4: V602 | GN4: V603 | GO4: V604 | GP4: V605 | GQ4: V610 | GR4: V701 | GS4: V702 | GT4: V711 | GU4: V712 | GV4: V750 | GW4: V801 | GX4: V900 | GY4: V904 | GZ4: V905 | HA4: V906 | HB4: V907 | HC4: V910 | HD4: V911 | HE4: V912 | HF4: V913 | HG4: V914 | HH4: V917 | HI4: V920 | HJ4: V922
A5: MFB-S | B5: A51 | C5: Torque | D5: F150/4*A51-K | E5: 1008219 | F5: 1013224 | G5: V379 | DV5: X
A6: MFB-S | B6: A52 | C6: Torque | D6: F150/4*A52-K | E6: 1008420 | F6: 1013224 | G6: V379 | DV6: X
A7: MFB-S | B7: A53 | C7: Torque | D7: F150/4*A53-K | E7: 1008218 | F7: 1013225 | G7: V309 | DB7: X
A8: MFB-S | B8: A54 | C8: Torque | D8: F150/4*A54-K | E8: 1008215 | F8: 1013225 | G8: V309 | DB8: X
A9: MFB-S | B9: A55 | C9: Torque | D9: F150/4*A55-K | F9: 1013225 | G9: -
A10: MFB-S | B10: A56 | C10: Torque | D10: F150/4*A56-K | F10: 1013225 | G10: -

Sheet Acomodos Modularidades
A2: V215 | B2: A2965401314 | C2: V215 | E2: A2965401314 | F2: A2965404603 | G2: A2965404203 | H2: A2965407703 | I2: A2965407103 | J2: A2965405003 | K2: A2965403314 | L2: A2965403718 | M2: A2965403818 | N2: A2965402414 | O2: A2965404108 | P2: A2965403008 | Q2: A2965409911 | R2: A2965404500 | S2: A2965404900 | T2: A2965404700 | U2: A2965403714 | V2: A2965409518 | W2: A2965402908 | X2: A2965400708 | Y2: A2965409718 | Z2: A2965400909 | AA2: A2965405300 | AB2: A2965405500 | AC2: A2965407300 | AD2: A2965403618 | AE2: A2965403418 | AF2: A2965409600 | AG2: A2965403908 | AH2: A2965408900 | AI2: A2965402514 | AJ2: A2965401914 | AK2: A2965403800 | AL2: A2965405318 | AM2: A2965404918 | AN2: A2965405118 | AO2: A2965409118 | AP2: A2965400608 | AQ2: A2965400508 | AR2: A2965406616 | AS2: A2965401213 | AT2: A2965407213 | AU2: A2965409712 | AV2: A2965401900 | AW2: A2965403000 | AX2: A2965402200 | AY2: A2965402214 | AZ2: A2965403600 | BA2: A2965403613 | BB2: A2965409014 | BC2: A2965408000 | BD2: A2965408100 | BE2: A2965408200 | BF2: A2965400008 | BG2: A2965405100 | BH2: A2965405700 | BI2: A2965408718 | BJ2: A2965401008 | BK2: A2965409912 | BL2: A2965402613 | BM2: A2965409312 | BN2: A2965403013 | BO2: A2965402319 | BP2: A2965404912 | BQ2: A2965403218 | BR2: A2965404803 | BS2: A2965406103 | BT2: A2965406303 | BU2: A2965406403 | BV2: A2965406603 | BW2: A2965406703 | BX2: A2965407203 | BY2: A2965407503 | BZ2: A2965407803 | CA2: A2965408103 | CB2: A2965408403 | CC2: A2965408803 | CD2: A2965403312 | CE2: A2965407903 | CF2: A2965408003 | CG2: A2965406413 | CH2: A2965406719 | CI2: A2965407013 | CJ2: A2965408404 | CK2: A2965406903 | CL2: A2965409500 | CM2: A2965409700 | CN2: A2965409708 | CO2: A2965409108 | CP2: A2965409308 | CQ2: A2965409807 | CR2: A2965406516 | CS2: A2965400108 | CT2: A2965409318 | CU2: A2965402808 | CV2: A2965403012 | CW2: A2965402000 | CX2: A2965402100 | CY2: A2965402400 | CZ2: A2965402500 | DA2: A2965402600 | DB2: A2965402800 | DC2: A2965403200 | DD2: A2965403300 | DE2: A2965403400 | DF2: A2965405518 | DG2: A2965409000 | DH2: A2965409100 | DI2: A2965403605 | DJ2: A2965406318 | DK2: A2965407000 | DL2: A2965404318 | DM2: A2965407600 | DN2: A2965407700 | DO2: A2965407800 | DP2: A2965407900 | DQ2: A2965407814 | DR2: A2965407216 | DS2: A2965404000 | DT2: A2965404518 | DU2: A2965404400 | DV2: A2965403705 | DW2: A2965409800 | DX2: A2965401719 | DY2: A2965400001 | DZ2: A2965407316 | EA2: A2965409511 | EB2: A2965409611 | EC2: A2965408808 | ED2: A2965406518 | EE2: A2965409507 | EF2: A2965403913 | EG2: A2965409411 | EH2: A2965408911 | EI2: A2965408511 | EJ2: A2965407911 | EK2: A2965406118 | EL2: A2965404718 | EM2: A2965408111 | EN2: A2965408211 | EO2: A2965404712 | EP2: A2965401113 | EQ2: A2965400513 | ER2: A2965407416 | ES2: A2965402814 | ET2: A2965403014 | EU2: A2965403214 | EV2: A2965403514 | EW2: A2965402614 | EX2: A2965402714 | EY2: A2965403614 | EZ2: A2965403814 | FA2: A2965400618 | FB2: A2965407518 | FC2: A2965407314 | FD2: A2965400713 | FE2: A2965401614 | FF2: A2965406014 | FG2: A2965401714 | FH2: A2965401814 | FI2: A2965402014 | FJ2: A2965403414 | FK2: A2965400101 | FL2: A2965408214 | FM2: A2965408514 | FN2: A2965400919 | FO2: A2965408918 | FP2: A2965409214 | FQ2: A2965408814 | FR2: A2965409414 | FS2: A2965401015 | FT2: A2965404115 | FU2: A2965404215 | FV2: A2965405416 | FW2: A2965405616 | FX2: A2965406315 | FY2: A2965400818 | FZ2: A2965407716 | GA2: A2965404015 | GB2: A2965406515 | GC2: A2965407118 | GD2: A2965406818 | GE2: A2965407018 | GF2: A2965400719 | GG2: A2965401119 | GH2: A2965404519 | GI2: A2965400319 | GJ2: A2965400119 | GK2: A2965400519 | GL2: A2965407816 | GM2: A2965404319 | GN2: A2965406119 | GO2: A2965407718 | GP2: A2965405713 | GQ2: A2965407516 | GR2: A2965402618 | GS2: A2965402818 | GT2: A2965408812 | GU2: A2965406212 | GV2: A2965409918 | GW2: A2965406812 | GX2: A2965406816 | GY2: A2965407812 | GZ2: A2965408212 | HA2: A2965406612 | HB2: A2965409012 | HC2: A2965408412 | HD2: A2965408612 | HE2: A2965406915 | HF2: A2965406419
A3: V62 | B3: A2965404603 | C3: V62 | E3: V215 | F3: V62 | G3: V60 | H3: V77 | I3: V74 | J3: V65 | K3: V711 | L3: V526 | M3: V525 | N3: V100 | O3: V368 | P3: V366 | Q3: V8 | R3: V9 | S3: V11 | T3: V10 | U3: V801 | V3: V358 | W3: V363 | X3: V360 | Y3: V359 | Z3: V1 | AA3: V14 | AB3: V13 | AC3: V532 | AD3: V533 | AE3: V240 | AF3: V242 | AG3: V305 | AH3: V521 | AI3: V132 | AJ3: V604 | AK3: V550 | AL3: V555 | AM3: V551 | AN3: V553 | AO3: V350 | AP3: V370 | AQ3: V355 | AR3: V354 | AS3: V702 | AT3: V158 | AU3: V23 | AV3: V502 | AW3: V511 | AX3: V505 | AY3: V254 | AZ3: V519 | BA3: V501 | BB3: V311 | BC3: V539 | BD3: V540 | BE3: V541 | BF3: V6 | BG3: V12 | BH3: V15 | BI3: V17 | BJ3: V18 | BK3: V20 | BL3: V2 | BM3: V38 | BN3: V48 | BO3: V49 | BP3: V50 | BQ3: V51 | BR3: V63 | BS3: V68 | BT3: V69 | BU3: V70 | BV3: V71 | BW3: V73 | BX3: V75 | BY3: V76 | BZ3: V79 | CA3: V81 | CB3: V83 | CC3: V86 | CD3: V91 | CE3: V96 | CF3: V97 | CG3: V151 | CH3: V155 | CI3: V157 | CJ3: V190 | CK3: V94 | CL3: V241 | CM3: V243 | CN3: V251 | CO3: V252 | CP3: V253 | CQ3: V351 | CR3: V353 | CS3: V356 | CT3: V357 | CU3: V362 | CV3: V369 | CW3: V503 | CX3: V504 | CY3: V507 | CZ3: V508 | DA3: V509 | DB3: V510 | DC3: V515 | DD3: V516 | DE3: V517 | DF3: V518 | DG3: V522 | DH3: V523 | DI3: V524 | DJ3: V528 | DK3: V529 | DL3: V531 | DM3: V535 | DN3: V536 | DO3: V537 | DP3: V538 | DQ3: V544 | DR3: V547 | DS3: V552 | DT3: V554 | DU3: V556 | DV3: V557 | DW3: V559 | DX3: V560 | DY3: V561 | DZ3: V566 | EA3: V569 | EB3: V570 | EC3: V571 | ED3: V572 | EE3: V584 | EF3: V590 | EG3: V591 | EH3: V592 | EI3: V593 | EJ3: V594 | EK3: V595 | EL3: V596 | EM3: V597 | EN3: V598 | EO3: V602 | EP3: V701 | EQ3: V133 | ER3: V567 | ES3: V16 | ET3: V19 | EU3: V29 | EV3: V30 | EW3: V31 | EX3: V32 | EY3: V33 | EZ3: V34 | FA3: V102 | FB3: V103 | FC3: V152 | FD3: V200 | FE3: V218 | FF3: V365 | FG3: V601 | FH3: V603 | FI3: V605 | FJ3: V712 | FK3: V574 | FL3: V93 | FM3: V89 | FN3: V136 | FO3: V255 | FP3: V309 | FQ3: V379 | FR3: V380 | FS3: V310 | FT3: V41 | FU3: V42 | FV3: V43 | FW3: V44 | FX3: V506 | FY3: V105 | FZ3: V750 | GA3: V258 | GB3: V45 | GC3: V140 | GD3: V110 | GE3: V111 | GF3: V138 | GG3: V139 | GH3: V106 | GI3: V134 | GJ3: V135 | GK3: V137 | GL3: V610 | GM3: V259 | GN3: V46 | GO3: V26 | GP3: V382 | GQ3: V381 | GR3: V256 | GS3: V257 | GT3: V911 | GU3: V904 | GV3: V905 | GW3: V910 | GX3: V900 | GY3: V914 | GZ3: V912 | HA3: V906 | HB3: V917 | HC3: V913 | HD3: V907 | HE3: V920 | HF3: V922
A4: V60 | B4: A2965404203 | C4: V60
A5: V77 | B5: A2965407703 | C5: V77
A6: V74 | B6: A2965407103 | C6: V74
A7: V65 | B7: A2965405003 | C7: V65
A8: V711 | B8: A2965403314 | C8: V711
A9: V526 | B9: A2965403718 | C9: V526
A10: V525 | B10: A2965403818 | C10: V525
A11: V100 | B11: A2965402414 | C11: V100
A12: V368 | B12: A2965404108 | C12: V368
A13: V366 | B13: A2965403008 | C13: V366
A14: V8 | B14: A2965409911 | C14: V8
A15: V9 | B15: A2965404500 | C15: V9
... A211: V922 | B211: A2965406419 | C211: V922
