Workbook

Sheet Matriz Interior Izquierda PDC-D
AG2: comun | AH2: Comun | AW2: Comun | AX2: Comun
A3: Fusibles | H3: A2965401009 | I3: A2965402713 | J3: A2965400008 | K3: A2965409911 | L3: A2965404600 | M3: A2965404800 | N3: A2965405000 | O3: A2965405200 | P3: A2965405600 | Q3: A2965405400 | R3: A2965405800 | S3: A2965403914 | T3: A2965408818 | U3: A2965401108 | V3: A2965404014 | W3: A2965400213 | X3: A2965409812 | Y3: A2965407818 | Z3: A2965404114 | AA3: A2965404214 | AB3: A2965404314 | AC3: A2965404414 | AD3: A2965404514 | AE3: A2965404614 | AF3: A2965409412 | AG3: A2965404115 | AH3: A2965404215 | AI3: A2965405516 | AJ3: A2965405716 | AK3: A2965406615 | AL3: A2965406619 | AM3: A2965403113 | AN3: A2965402419 | AO3: A2965402109 | AP3: A2965403318 | AQ3: A2965404303 | AR3: A2965404703 | AS3: A2965404903 | AT3: A2965405103 | AU3: A2965406203 | AV3: A2965406503 | AW3: A2965406603 | AX3: A2965406703 | AY3: A2965407303 | AZ3: A2965407403 | BA3: A2965407703 | BB3: A2965408103 | BC3: A2965408503 | BD3: A2965408903 | BE3: A2965408514 | BF3: A2965403412 | BG3: A2965408214 | BH3: A2965406903 | BI3: A2965407903 | BJ3: A2965405314 | BK3: A2965400718 | BL3: A2965407618 | BM3: A2965400918 | BN3: A2965404619 | BO3: A2965406918 | BP3: A2965405614 | BQ3: A2965400613 | BR3: A2965400419 | BS3: A2965400219 | BT3: A2965401019 | BU3: A2965400619 | BV3: A2965400819 | BW3: A2965401219 | BX3: A2965407218 | BY3: A2965406513 | BZ3: A2965407614 | CA3: A2965406819 | CB3: A2965407113 | CC3: A2965407313 | CD3: A2965408504 | CE3: A2965400813 | CF3: A2965401314 | CG3: A2965405714 | CH3: A2965403518 | CI3: A2965409500 | CJ3: A2965409600 | CK3: A2965409700 | CL3: A2965409808 | CM3: A2965409208 | CN3: A2965409408 | CO3: A2965404914 | CP3: A2965409018 | CQ3: A2965402718 | CR3: A2965402918 | CS3: A2965404015 | CT3: A2965404419 | CU3: A2965408515 | CV3: A2965409314 | CW3: A2965401115 | CX3: A2965409114 | CY3: A2965409218 | CZ3: A2965405112 | DA3: A2965406516 | DB3: A2965406716 | DC3: A2965406814 | DD3: A2965407014 | DE3: A2965409418 | DF3: A2965409618 | DG3: A2965409818 | DH3: A2965400708 | DI3: A2965407114 | DJ3: A2965402908 | DK3: A2965406114 | DL3: A2965403108 | DM3: A2965404008 | DN3: A2965403112 | DO3: A2965406914 | DP3: A2965408914 | DQ3: A2965409514 | DR3: A2965407616 | DS3: A2965406614 | DT3: A2965406113 | DU3: A2965404113 | DV3: A2965404213 | DW3: A2965404313 | DX3: A2965402300 | DY3: A2965406415 | DZ3: A2965404719 | EA3: A2965404819 | EB3: A2965402700 | EC3: A2965402900 | ED3: A2965403100 | EE3: A2965404413 | EF3: A2965403400 | EG3: A2965405618 | EH3: A2965403700 | EI3: A2965405013 | EJ3: A2965405113 | EK3: A2965405213 | EL3: A2965403605 | EM3: A2965404218 | EN3: A2965404118 | EO3: A2965406418 | EP3: A2965404418 | EQ3: A2965407300 | ER3: A2965403918 | ES3: A2965407600 | ET3: A2965407700 | EU3: A2965407800 | EV3: A2965407900 | EW3: A2965408000 | EX3: A2965408100 | EY3: A2965408300 | EZ3: A2965407914 | FA3: A2965407216 | FB3: A2965403800 | FC3: A2965405018 | FD3: A2965404000 | FE3: A2965405218 | FF3: A2965404618 | FG3: A2965405418 | FH3: A2965404400 | FI3: A2965403705 | FJ3: A2965405313 | FK3: A2965406718 | FL3: A2965405413 | FM3: A2965407316 | FN3: A2965407416 | FO3: A2965409511 | FP3: A2965406618 | FQ3: A2965400101 | FR3: A2965409607 | FS3: A2965404013 | FT3: A2965409411 | FU3: A2965408911 | FV3: A2965408511 | FW3: A2965407911 | FX3: A2965406218 | FY3: A2965404818 | FZ3: A2965408111 | GA3: A2965408211 | GB3: A2965405014 | GC3: A2965404812 | GD3: A2965405214 | GE3: A2965405114 | GF3: A2965405012 | GG3: A2965407916 | GH3: A2965401113 | GI3: A2965401213 | GJ3: A2965403314 | GK3: A2965403414 | GL3: A2965401718 | GM3: A2965405914 | GN3: A2965406916 | GO3: A2965406312 | GP3: A2965400019 | GQ3: A2965406712 | GR3: A2965408712 | GS3: A2965406912 | GT3: A2965408912 | GU3: A2965408312 | GV3: A2965408512 | GW3: A2965407912 | GX3: A2965409112 | GY3: A2965407015 | GZ3: A2965406519
A4: Subensamble | B4: kurzname | C4: Descripcion | D4: # Mercedez | E4: Oracle (s) | F4: Variante | G4: Amp | H4: V1 | I4: V2 | J4: V6 | K4: V8 | L4: V9 | M4: V10 | N4: V11 | O4: V12 | P4: V13 | Q4: V14 | R4: V15 | S4: V16 | T4: V17 | U4: V18 | V4: V19 | W4: V20 | X4: V23 | Y4: V26 | Z4: V29 | AA4: V30 | AB4: V31 | AC4: V32 | AD4: V33 | AE4: V34 | AF4: V38 | AG4: V41 | AH4: V42 | AI4: V43 | AJ4: V44 | AK4: V45 | AL4: V46 | AM4: V48 | AN4: V49 | AO4: V50 | AP4: V51 | AQ4: V60 | AR4: V62 | AS4: V63 | AT4: V65 | AU4: V68 | AV4: V70 | AW4: V71 | AX4: V73 | AY4: V74 | AZ4: V75 | BA4: V77 | BB4: V81 | BC4: V83 | BD4: V86 | BE4: V89 | BF4: V91 | BG4: V93 | BH4: V94 | BI4: V96 | BJ4: V100 | BK4: V102 | BL4: V103 | BM4: V105 | BN4: V106 | BO4: V110 | BP4: V132 | BQ4: V133 | BR4: V134 | BS4: V135 | BT4: V136 | BU4: V137 | BV4: V138 | BW4: V139 | BX4: V140 | BY4: V151 | BZ4: V152 | CA4: V155 | CB4: V157 | CC4: V158 | CD4: V190 | CE4: V200 | CF4: V215 | CG4: V218 | CH4: V240 | CI4: V241 | CJ4: V242 | CK4: V243 | CL4: V251 | CM4: V252 | CN4: V253 | CO4: V254 | CP4: V255 | CQ4: V256 | CR4: V257 | CS4: V258 | CT4: V259 | CU4: V305 | CV4: V309 | CW4: V310 | CX4: V311 | CY4: V350 | CZ4: V351 | DA4: V353 | DB4: V354 | DC4: V355 | DD4: V356 | DE4: V357 | DF4: V358 | DG4: V359 | DH4: V360 | DI4: V362 | DJ4: V363 | DK4: V365 | DL4: V366 | DM4: V368 | DN4: V369 | DO4: V370 | DP4: V379 | DQ4: V380 | DR4: V381 | DS4: V382 | DT4: V501 | DU4: V502 | DV4: V503 | DW4: V504 | DX4: V505 | DY4: V506 | DZ4: V507 | EA4: V508 | EB4: V509 | EC4: V510 | ED4: V511 | EE4: V516 | EF4: V517 | EG4: V518 | EH4: V519 | EI4: V521 | EJ4: V522 | EK4: V523 | EL4: V524 | EM4: V525 | EN4: V526 | EO4: V528 | EP4: V531 | EQ4: V532 | ER4: V533 | ES4: V535 | ET4: V536 | EU4: V537 | EV4: V538 | EW4: V539 | EX4: V540 | EY4: V541 | EZ4: V544 | FA4: V547 | FB4: V550 | FC4: V551 | FD4: V552 | FE4: V553 | FF4: V554 | FG4: V555 | FH4: V556 | FI4: V557 | FJ4: V559 | FK4: V560 | FL4: V561 | FM4: V566 | FN4: V567 | FO4: V569 | FP4: V572 | FQ4: V574 | FR4: V584 | FS4: V590 | FT4: V591 | FU4: V592 | FV4: V593 | FW4: V594 | FX4: V595 | FY4: V596 | FZ4: V597 | GA4: V598 | GB4: V601 | GC4: V602 | GD4: V603 | GE4: V604 | GF4: V605 | GG4: V610 | GH4: V701 | GI4: V702 | GJ4: V711 | GK4: V712 | GL4: V750 | GM4: V801 | GN4: V900 | GO4: V904 | GP4: V905 | GQ4: V906 | GR4: V907 | GS4: V910 | GT4: V911 | GU4: V912 | GV4: V913 | GW4: V914 | GX4: V917 | GY4: V920 | GZ4: V922
A5: PDC-D | B5: F200 | C5: Fusible | D5: N000000008708 | E5: 1012166 | F5: V1 | G5: 5A | H5: X
A6: PDC-D | B6: F201 | C6: Fusible | D6: N000000008709 | E6: 1012168 | F6: V523 | G6: 7.5A | EK6: X
A7: PDC-D | B7: F202 | C7: Fusible | D7: N000000008710 | E7: 1012170 | F7: V590 | G7: 10A | FS7: X
A8: PDC-D | B8: F203 | C8: Fusible | D8: N000000008708 | E8: 1012166 | F8: V559 | G8: 5A | FJ8: X
A9: PDC-D | B9: F204 | C9: Fusible | D9: N000000008710 | E9: 1012170 | F9: V1 | G9: 10A | H9: X
A10: PDC-D | B10: F205 | C10: Fusible | D10: N000000008708 | E10: 1012166 | F10: V362 | G10: 5A | DI10: X | DJ10: X
A11: PDC-D | B11: F206 | C11: Fusible | D11: N000000008710 | E11: 1012170 | F11: V590 | G11: 10A | FS11: X
A12: PDC-D | B12: F207 | C12: Fusible | D12: N000000008710 | E12: 1012170 | F12: V157 | G12: 10A | CB12: X
A13: PDC-D | B13: F208 | C13: Fusible | D13: N000000008710 | E13: 1012170 | F13: V157 | G13: 10A | CB13: X
A14: PDC-D | B14: F209 | C14: Fusible | D14: N000000008704 | E14: 1012173 | F14: V1 | G14: 30A | H14: X
A15: PDC-D | B15: F210 | C15: Fusible | D15: N000000008708 | E15: 1012166 | F15: V255 | G15: 5A | CP15: X
A16: PDC-D | B16: F211 | C16: Fusible | D16: N000000008704 | E16: 1012173 | F16: V1 | G16: 30A | H16: X
A17: PDC-D | B17: F212 | C17: Fusible | D17: N000000008704 | E17: 1012173 | F17: V252 | G17: 30A | CM17: X
A18: PDC-D | B18: F213 | C18: Fusible | D18: N000000008708 | E18: 1012166 | F18: V1 | G18: 5A | H18: X
A19: PDC-D | B19: F214 | C19: Fusible | D19: N000000008704 | E19: 1012173 | F19: V1 | G19: 30A | H19: X
A20: PDC-D | B20: F215 | C20: Fusible | D20: N000000008704 | E20: 1012173 | F20: V1 | G20: 30A | H20: X
A21: PDC-D | B21: F216 | C21: Fusible | D21: N000000008703 | E21: 1012171 | F21: V1 | G21: 25A | H21: X
A22: PDC-D | B22: F217 | C22: Fusible | D22: N000000008711 | E22: 1012169 | F22: V1 | G22: 15A | H22: X
A23: PDC-D | B23: F218 | C23: Fusible | D23: N000000008708 | E23: 1012166 | F23: V1 | G23: 5A | H23: X
A24: PDC-D | B24: F219 | C24: Fusible | D24: N000000008710 | E24: 1012170 | F24: V1 | G24: 10A | H24: X
A25: PDC-D | B25: F220 | C25: Fusible | D25: N000000008708 | E25: 1012166 | F25: V1 | G25: 5A | H25: X
A26: PDC-D | B26: F221 | C26: Fusible | D26: N000000008711 | E26: 1012169 | F26: V1 | G26: 15A | H26: X
A27: PDC-D | B27: F222 | C27: Fusible | D27: N000000008710 | E27: 1012170 | F27: V1 | G27: 10A | H27: X
A28: PDC-D | B28: F223 | C28: Fusible | D28: N000000008709 | E28: 1012168 | F28: V610 | G28: 7.5A | GG28: X
A29: PDC-D | B29: F224 | C29: Fusible | D29: N000000008709 | E29: 1012168 | F29: V1 | G29: 7.5A | H29: X
A30: PDC-D | B30: F225 | C30: Fusible | D30: N000000008711 | E30: 1012169 | F30: V1 | G30: 15A | H30: X
A31: PDC-D | B31: F226 | C31: Fusible | D31: N000000008709 | E31: 1012168 | F31: V1 | G31: 7.5A | H31: X
A32: PDC-D | B32: F227 | C32: Fusible | D32: N000000008708 | E32: 1012166 | F32: V1 | G32: 5A | H32: X
A33: PDC-D | B33: F229 | C33: Fusible | D33: N000000008708 | E33: 1012166 | F33: V1 | G33: 5A | H33: X
A34: PDC-D | B34: F230 | C34: Fusible | D34: N000000008708 | E34: 1012166 | F34: V1 | G34: 5A | H34: X
A35: PDC-D | B35: F231 | C35: Fusible | D35: N000000008708 | E35: 1012166 | F35: V1 | G35: 5A | H35: X

Sheet Matriz Interior Izquierda PDC-P
A3: Fusibles | H3: A2965401009 | I3: A2965402713 | J3: A2965400008 | K3: A2965409911 | L3: A2965404600 | M3: A2965404800 | N3: A2965405000 | O3: A2965405200 | P3: A2965405600 | Q3: A2965405400 | R3: A2965405800 | S3: A2965403914 | T3: A2965408818 | U3: A2965401108 | V3: A2965404014 | W3: A2965400213 | X3: A2965409812 | Y3: A2965407818 | Z3: A2965404114 | AA3: A2965404214 | AB3: A2965404314 | AC3: A2965404414 | AD3: A2965404514 | AE3: A2965404614 | AF3: A2965409412 | AG3: A2965404115 | AH3: A2965404215 | AI3: A2965405516 | AJ3: A2965405716 | AK3: A2965406615 | AL3: A2965406619 | AM3: A2965403113 | AN3: A2965402419 | AO3: A2965402109 | AP3: A2965403318 | AQ3: A2965404303 | AR3: A2965404703 | AS3: A2965404903 | AT3: A2965405103 | AU3: A2965406203 | AV3: A2965406503 | AW3: A2965406603 | AX3: A2965406703 | AY3: A2965407303 | AZ3: A2965407403 | BA3: A2965407703 | BB3: A2965408103 | BC3: A2965408503 | BD3: A2965408903 | BE3: A2965408514 | BF3: A2965403412 | BG3: A2965408214 | BH3: A2965406903 | BI3: A2965407903 | BJ3: A2965405314 | BK3: A2965400718 | BL3: A2965407618 | BM3: A2965400918 | BN3: A2965404619 | BO3: A2965406918 | BP3: A2965405614 | BQ3: A2965400613 | BR3: A2965400419 | BS3: A2965400219 | BT3: A2965401019 | BU3: A2965400619 | BV3: A2965400819 | BW3: A2965401219 | BX3: A2965407218 | BY3: A2965406513 | BZ3: A2965407614 | CA3: A2965406819 | CB3: A2965407113 | CC3: A2965407313 | CD3: A2965408504 | CE3: A2965400813 | CF3: A2965401314 | CG3: A2965405714 | CH3: A2965403518 | CI3: A2965409500 | CJ3: A2965409600 | CK3: A2965409700 | CL3: A2965409808 | CM3: A2965409208 | CN3: A2965409408 | CO3: A2965404914 | CP3: A2965409018 | CQ3: A2965402718 | CR3: A2965402918 | CS3: A2965404015 | CT3: A2965404419 | CU3: A2965408515 | CV3: A2965409314 | CW3: A2965401115 | CX3: A2965409114 | CY3: A2965409218 | CZ3: A2965405112 | DA3: A2965406516 | DB3: A2965406716 | DC3: A2965406814 | DD3: A2965407014 | DE3: A2965409418 | DF3: A2965409618 | DG3: A2965409818 | DH3: A2965400708 | DI3: A2965407114 | DJ3: A2965402908 | DK3: A2965406114 | DL3: A2965403108 | DM3: A2965404008 | DN3: A2965403112 | DO3: A2965406914 | DP3: A2965408914 | DQ3: A2965409514 | DR3: A2965407616 | DS3: A2965406614 | DT3: A2965406113 | DU3: A2965404113 | DV3: A2965404213 | DW3: A2965404313 | DX3: A2965402300 | DY3: A2965406415 | DZ3: A2965404719 | EA3: A2965404819 | EB3: A2965402700 | EC3: A2965402900 | ED3: A2965403100 | EE3: A2965404413 | EF3: A2965403400 | EG3: A2965405618 | EH3: A2965403700 | EI3: A2965405013 | EJ3: A2965405113 | EK3: A2965405213 | EL3: A2965403605 | EM3: A2965404218 | EN3: A2965404118 | EO3: A2965406418 | EP3: A2965404418 | EQ3: A2965407300 | ER3: A2965403918 | ES3: A2965407600 | ET3: A2965407700 | EU3: A2965407800 | EV3: A2965407900 | EW3: A2965408000 | EX3: A2965408100 | EY3: A2965408300 | EZ3: A2965407914 | FA3: A2965407216 | FB3: A2965403800 | FC3: A2965405018 | FD3: A2965404000 | FE3: A2965405218 | FF3: A2965404618 | FG3: A2965405418 | FH3: A2965404400 | FI3: A2965403705 | FJ3: A2965405313 | FK3: A2965406718 | FL3: A2965405413 | FM3: A2965407316 | FN3: A2965407416 | FO3: A2965409511 | FP3: A2965406618 | FQ3: A2965400101 | FR3: A2965409607 | FS3: A2965404013 | FT3: A2965409411 | FU3: A2965408911 | FV3: A2965408511 | FW3: A2965407911 | FX3: A2965406218 | FY3: A2965404818 | FZ3: A2965408111 | GA3: A2965408211 | GB3: A2965405014 | GC3: A2965404812 | GD3: A2965405214 | GE3: A2965405114 | GF3: A2965405012 | GG3: A2965407916 | GH3: A2965401113 | GI3: A2965401213 | GJ3: A2965403314 | GK3: A2965403414 | GL3: A2965401718 | GM3: A2965405914 | GN3: A2965406916 | GO3: A2965406312 | GP3: A2965400019 | GQ3: A2965406712 | GR3: A2965408712 | GS3: A2965406912 | GT3: A2965408912 | GU3: A2965408312 | GV3: A2965408512 | GW3: A2965407912 | GX3: A2965409112 | GY3: A2965407015 | GZ3: A2965406519 | HA3: =VLOOKUP(HA4,'Acomodos Modularidades'!$A$2:$B$211,2,FALSE) -> A2965408612 | HB3: =VLOOKUP(HB4,'Acomodos Modularidades'!$A$2:$B$211,2,FALSE) -> A2965406812 | HC3: =VLOOKUP(HC4,'Acomodos Modularidades'!$A$2:$B$211,2,FALSE) -> A2965408812 | HD3: =VLOOKUP(HD4,'Acomodos Modularidades'!$A$2:$B$211,2,FALSE) -> A2965408212 | HE3: =VLOOKUP(HE4,'Acomodos Modularidades'!$A$2:$B$211,2,FALSE) -> A2965408412 | HF3: =VLOOKUP(HF4,'Acomodos Modularidades'!$A$2:$B$211,2,FALSE) -> A2965407812 | HG3: =VLOOKUP(HG4,'Acomodos Modularidades'!$A$2:$B$211,2,FALSE) -> A2965409012 | HH3: =VLOOKUP(HH4,'Acomodos Modularidades'!$A$2:$B$211,2,FALSE) -> A2965406915 | HI3: =VLOOKUP(HI4,'Acomodos Modularidades'!$A$2:$B$211,2,FALSE) -> A2965406419
A4: Subensamble | B4: kurzname | C4: Descripcion | D4: # Mercedez | E4: Oracle (s) | F4: Variante | G4: Amp | H4: V1 | I4: V2 | J4: V6 | K4: V8 | L4: V9 | M4: V10 | N4: V11 | O4: V12 | P4: V13 | Q4: V14 | R4: V15 | S4: V16 | T4: V17 | U4: V18 | V4: V19 | W4: V20 | X4: V23 | Y4: V26 | Z4: V29 | AA4: V30 | AB4: V31 | AC4: V32 | AD4: V33 | AE4: V34 | AF4: V38 | AG4: V41 | AH4: V42 | AI4: V43 | AJ4: V44 | AK4: V45 | AL4: V46 | AM4: V48 | AN4: V49 | AO4: V50 | AP4: V51 | AQ4: V60 | AR4: V62 | AS4: V63 | AT4: V65 | AU4: V68 | AV4: V69 | AW4: V70 | AX4: V71 | AY4: V73 | AZ4: V74 | BA4: V75 | BB4: V76 | BC4: V77 | BD4: V79 | BE4: V81 | BF4: V83 | BG4: V86 | BH4: V89 | BI4: V91 | BJ4: V93 | BK4: V94 | BL4: V96 | BM4: V97 | BN4: V100 | BO4: V102 | BP4: V103 | BQ4: V105 | BR4: V106 | BS4: V110 | BT4: V111 | BU4: V132 | BV4: V133 | BW4: V134 | BX4: V135 | BY4: V136 | BZ4: V137 | CA4: V138 | CB4: V139 | CC4: V140 | CD4: V151 | CE4: V152 | CF4: V155 | CG4: V157 | CH4: V158 | CI4: V190 | CJ4: V200 | CK4: V215 | CL4: V218 | CM4: V240 | CN4: V241 | CO4: V242 | CP4: V243 | CQ4: V251 | CR4: V252 | CS4: V253 | CT4: V254 | CU4: V255 | CV4: V256 | CW4: V257 | CX4: V258 | CY4: V259 | CZ4: V305 | DA4: V309 | DB4: V310 | DC4: V311 | DD4: V350 | DE4: V351 | DF4: V353 | DG4: V354 | DH4: V355 | DI4: V356 | DJ4: V357 | DK4: V358 | DL4: V359 | DM4: V360 | DN4: V362 | DO4: V363 | DP4: V365 | DQ4: V366 | DR4: V368 | DS4: V369 | DT4: V370 | DU4: V379 | DV4: V380 | DW4: V381 | DX4: V382 | DY4: V501 | DZ4: V502 | EA4: V503 | EB4: V504 | EC4: V505 | ED4: V506 | EE4: V507 | EF4: V508 | EG4: V509 | EH4: V510 | EI4: V511 | EJ4: V515 | EK4: V516 | EL4: V517 | EM4: V518 | EN4: V519 | EO4: V521 | EP4: V522 | EQ4: V523 | ER4: V524 | ES4: V525 | ET4: V526 | EU4: V528 | EV4: V529 | EW4: V531 | EX4: V532 | EY4: V533 | EZ4: V535 | FA4: V536 | FB4: V537 | FC4: V538 | FD4: V539 | FE4: V540 | FF4: V541 | FG4: V544 | FH4: V547 | FI4: V550 | FJ4: V551 | FK4: V552 | FL4: V553 | FM4: V554 | FN4: V555 | FO4: V556 | FP4: V557 | FQ4: V559 | FR4: V560 | FS4: V561 | FT4: V566 | FU4: V567 | FV4: V569 | FW4: V570 | FX4: V571 | FY4: V572 | FZ4: V574 | GA4: V584 | GB4: V590 | GC4: V591 | GD4: V592 | GE4: V593 | GF4: V594 | GG4: V595 | GH4: V596 | GI4: V597 | GJ4: V598 | GK4: V601 | GL4: V602 | GM4: V603 | GN4: V604 | GO4: V605 | GP4: V610 | GQ4: V701 | GR4: V702 | GS4: V711 | GT4: V712 | GU4: V750 | GV4: V801 | GW4: V900 | GX4: V904 | GY4: V905 | GZ4: V906 | HA4: V907 | HB4: V910 | HC4: V911 | HD4: V912 | HE4: V913 | HF4: V914 | HG4: V917 | HH4: V920 | HI4: V922
A5: PDC-P | B5: F300 | C5: Fusible | D5: N000000008701 | E5: 1012172 | F5: V1 | G5: 15A | H5: X
A6: PDC-P | B6: F302 | C6: Fusible | D6: N000000008708 | E6: 1012166 | F6: V50 | G6: 5A | AO6: X
A7: PDC-P | B7: F303 | C7: Fusible | D7: N000000008708 | E7: 1012166 | F7: V50 | G7: 5A | AO7: X
A8: PDC-P | B8: F304 | C8: Fusible | D8: N000000008708 | E8: 1012166 | F8: V541 | G8: 5A | FF8: X
A9: PDC-P | B9: F318 | C9: Fusible | D9: N000000008709 | E9: 1012168 | F9: V60 | G9: 7.5A | AQ9: X
A10: PDC-P | B10: F319 | C10: Fusible | D10: N000000008709 | E10: 1012168 | F10: V521 | G10: 7.5A | EO10: X
A11: PDC-P | B11: F320 | C11: Fusible | D11: N000000008709 | E11: 1012168 | F11: V1 | G11: 7.5A | H11: X
A12: PDC-P | B12: F321 | C12: Fusible | D12: N000000008709 | E12: 1012168 | F12: V801 | G12: 7.5A | GV12: X
A13: PDC-P | B13: F322 | C13: Fusible | D13: N000000008709 | E13: 1012168 | F13: V1 | G13: 7.5A | H13: X
A14: PDC-P | B14: F323 | C14: Fusible | D14: N000000008709 | E14: 1012168 | F14: V357/V358 | G14: 7.5A | DJ14: X | DK14: X
A15: PDC-P | B15: F326 | C15: Fusible | D15: N000000008704 | E15: 1012173 | F15: V1 | G15: 30A | H15: X
A16: PDC-P | B16: F327 | C16: Fusible | D16: N000000008704 | E16: 1012173 | F16: V501 | G16: 30A | DY16: X
A17: PDC-P | B17: F328 | C17: Fusible | D17: N000000008704 | E17: 1012173 | F17: V151 | G17: 30A | CD17: X
A18: PDC-P | B18: F329 | C18: Fusible | D18: N000000008704 | E18: 1012173 | F18: V151 | G18: 30A | CD18: X
A19: PDC-P | B19: F330 | C19: Fusible | D19: N000000008704 | E19: 1012173 | F19: V152 | G19: 30A | CE19: X
A20: PDC-P | B20: F331 | C20: Fusible | D20: N000000008704 | E20: 1012173 | F20: V252 | G20: 30A | CR20: X
A21: PDC-P | B21: F332 | C21: Fusible | D21: N000000008701 | E21: 1012172 | F21: V1 | G21: 15A | H21: X
A22: PDC-P | B22: F333 | C22: Fusible | D22: N000000008704 | E22: 1012173 | F22: V200 | G22: 30A | CJ22: X
A23: PDC-P | B23: F334 | C23: Fusible | D23: N000000008704 | E23: 1012173 | F23: V200 | G23: 30A | CJ23: X
A24: PDC-P | B24: F335 | C24: Fusible | D24: N000000008703 | E24: 1012171 | F24: V1 | G24: 25A | H24: X
A25: PDC-P | B25: F301 | C25: Fusible | D25: N000000008711 | E25: 1012169 | F25: V900 | G25: 15A | GW25: X
A26: PDC-P | B26: MF1 | C26: Multifuse | D26: N000000006466 | E26: 1012146 | F26: V103/ V155 | G26: 7.5A | BP26: X | CF26: X
A27: PDC-P | B27: MF2 | C27: Multifuse | D27: N000000006465 | E27: 1012147 | F27: V362/ V363 | G27: 5A | DN27: X | DO27: X

Sheet Matriz Interior Izquierda PDC-R
A3: Fusibles | H3: A2965401009 | I3: A2965402713 | J3: A2965400008 | K3: A2965409911 | L3: A2965404600 | M3: A2965404800 | N3: A2965405000 | O3: A2965405200 | P3: A2965405600 | Q3: A2965405400 | R3: A2965405800 | S3: A2965403914 | T3: A2965408818 | U3: A2965401108 | V3: A2965404014 | W3: A2965400213 | X3: A2965409812 | Y3: A2965407818 | Z3: A2965404114 | AA3: A2965404214 | AB3: A2965404314 | AC3: A2965404414 | AD3: A2965404514 | AE3: A2965404614 | AF3: A2965409412 | AG3: A2965404115 | AH3: A2965404215 | AI3: A2965405516 | AJ3: A2965405716 | AK3: A2965406615 | AL3: A2965406619 | AM3: A2965403113 | AN3: A2965402419 | AO3: A2965402109 | AP3: A2965403318 | AQ3: A2965404303 | AR3: A2965404703 | AS3: A2965404903 | AT3: A2965405103 | AU3: A2965406203 | AV3: A2965406503 | AW3: A2965406603 | AX3: A2965406703 | AY3: A2965407303 | AZ3: A2965407403 | BA3: A2965407703 | BB3: A2965408103 | BC3: A2965408503 | BD3: A2965408903 | BE3: A2965408514 | BF3: A2965403412 | BG3: A2965408214 | BH3: A2965406903 | BI3: A2965407903 | BJ3: A2965405314 | BK3: A2965400718 | BL3: A2965407618 | BM3: A2965400918 | BN3: A2965404619 | BO3: A2965406918 | BP3: A2965405614 | BQ3: A2965400613 | BR3: A2965400419 | BS3: A2965400219 | BT3: A2965401019 | BU3: A2965400619 | BV3: A2965400819 | BW3: A2965401219 | BX3: A2965407218 | BY3: A2965406513 | BZ3: A2965407614 | CA3: A2965406819 | CB3: A2965407113 | CC3: A2965407313 | CD3: A2965408504 | CE3: A2965400813 | CF3: A2965401314 | CG3: A2965405714 | CH3: A2965403518 | CI3: A2965409500 | CJ3: A2965409600 | CK3: A2965409700 | CL3: A2965409808 | CM3: A2965409208 | CN3: A2965409408 | CO3: A2965404914 | CP3: A2965409018 | CQ3: A2965402718 | CR3: A2965402918 | CS3: A2965404015 | CT3: A2965404419 | CU3: A2965408515 | CV3: A2965409314 | CW3: A2965401115 | CX3: A2965409114 | CY3: A2965409218 | CZ3: A2965405112 | DA3: A2965406516 | DB3: A2965406716 | DC3: A2965406814 | DD3: A2965407014 | DE3: A2965409418 | DF3: A2965409618 | DG3: A2965409818 | DH3: A2965400708 | DI3: A2965407114 | DJ3: A2965402908 | DK3: A2965406114 | DL3: A2965403108 | DM3: A2965404008 | DN3: A2965403112 | DO3: A2965406914 | DP3: A2965408914 | DQ3: A2965409514 | DR3: A2965407616 | DS3: A2965406614 | DT3: A2965406113 | DU3: A2965404113 | DV3: A2965404213 | DW3: A2965404313 | DX3: A2965402300 | DY3: A2965406415 | DZ3: A2965404719 | EA3: A2965404819 | EB3: A2965402700 | EC3: A2965402900 | ED3: A2965403100 | EE3: A2965404413 | EF3: A2965403400 | EG3: A2965405618 | EH3: A2965403700 | EI3: A2965405013 | EJ3: A2965405113 | EK3: A2965405213 | EL3: A2965403605 | EM3: A2965404218 | EN3: A2965404118 | EO3: A2965406418 | EP3: A2965404418 | EQ3: A2965407300 | ER3: A2965403918 | ES3: A2965407600 | ET3: A2965407700 | EU3: A2965407800 | EV3: A2965407900 | EW3: A2965408000 | EX3: A2965408100 | EY3: A2965408300 | EZ3: A2965407914 | FA3: A2965407216 | FB3: A2965403800 | FC3: A2965405018 | FD3: A2965404000 | FE3: A2965405218 | FF3: A2965404618 | FG3: A2965405418 | FH3: A2965404400 | FI3: A2965403705 | FJ3: A2965405313 | FK3: A2965406718 | FL3: A2965405413 | FM3: A2965407316 | FN3: A2965407416 | FO3: A2965409511 | FP3: A2965406618 | FQ3: A2965400101 | FR3: A2965409607 | FS3: A2965404013 | FT3: A2965409411 | FU3: A2965408911 | FV3: A2965408511 | FW3: A2965407911 | FX3: A2965406218 | FY3: A2965404818 | FZ3: A2965408111 | GA3: A2965408211 | GB3: A2965405014 | GC3: A2965404812 | GD3: A2965405214 | GE3: A2965405114 | GF3: A2965405012 | GG3: A2965407916 | GH3: A2965401113 | GI3: A2965401213 | GJ3: A2965403314 | GK3: A2965403414 | GL3: A2965401718 | GM3: A2965405914 | GN3: A2965406916 | GO3: A2965406312 | GP3: A2965400019 | GQ3: A2965406712 | GR3: A2965408712 | GS3: A2965406912 | GT3: A2965408912 | GU3: A2965408312 | GV3: A2965408512 | GW3: A2965407912 | GX3: A2965409112 | GY3: A2965407015 | GZ3: A2965406519 | HA3: =VLOOKUP(HA4,'Acomodos Modularidades'!$A$2:$B$211,2,FALSE) -> A2965408612 | HB3: =VLOOKUP(HB4,'Acomodos Modularidades'!$A$2:$B$211,2,FALSE) -> A2965406812 | HC3: =VLOOKUP(HC4,'Acomodos Modularidades'!$A$2:$B$211,2,FALSE) -> A2965408812 | HD3: =VLOOKUP(HD4,'Acomodos Modularidades'!$A$2:$B$211,2,FALSE) -> A2965408212 | HE3: =VLOOKUP(HE4,'Acomodos Modularidades'!$A$2:$B$211,2,FALSE) -> A2965408412 | HF3: =VLOOKUP(HF4,'Acomodos Modularidades'!$A$2:$B$211,2,FALSE) -> A2965407812 | HG3: =VLOOKUP(HG4,'Acomodos Modularidades'!$A$2:$B$211,2,FALSE) -> A2965409012 | HH3: =VLOOKUP(HH4,'Acomodos Modularidades'!$A$2:$B$211,2,FALSE) -> A2965406915 | HI3: =VLOOKUP(HI4,'Acomodos Modularidades'!$A$2:$B$211,2,FALSE) -> A2965406419
A4: Subensamble | B4: kurzname | C4: Descripcion | D4: # Mercedez | E4: Oracle (s) | F4: Variante | G4: Amp | H4: V1 | I4: V2 | J4: V6 | K4: V8 | L4: V9 | M4: V10 | N4: V11 | O4: V12 | P4: V13 | Q4: V14 | R4: V15 | S4: V16 | T4: V17 | U4: V18 | V4: V19 | W4: V20 | X4: V23 | Y4: V26 | Z4: V29 | AA4: V30 | AB4: V31 | AC4: V32 | AD4: V33 | AE4: V34 | AF4: V38 | AG4: V41 | AH4: V42 | AI4: V43 | AJ4: V44 | AK4: V45 | AL4: V46 | AM4: V48 | AN4: V49 | AO4: V50 | AP4: V51 | AQ4: V60 | AR4: V62 | AS4: V63 | AT4: V65 | AU4: V68 | AV4: V69 | AW4: V70 | AX4: V71 | AY4: V73 | AZ4: V74 | BA4: V75 | BB4: V76 | BC4: V77 | BD4: V79 | BE4: V81 | BF4: V83 | BG4: V86 | BH4: V89 | BI4: V91 | BJ4: V93 | BK4: V94 | BL4: V96 | BM4: V97 | BN4: V100 | BO4: V102 | BP4: V103 | BQ4: V105 | BR4: V106 | BS4: V110 | BT4: V111 | BU4: V132 | BV4: V133 | BW4: V134 | BX4: V135 | BY4: V136 | BZ4: V137 | CA4: V138 | CB4: V139 | CC4: V140 | CD4: V151 | CE4: V152 | CF4: V155 | CG4: V157 | CH4: V158 | CI4: V190 | CJ4: V200 | CK4: V215 | CL4: V218 | CM4: V240 | CN4: V241 | CO4: V242 | CP4: V243 | CQ4: V251 | CR4: V252 | CS4: V253 | CT4: V254 | CU4: V255 | CV4: V256 | CW4: V257 | CX4: V258 | CY4: V259 | CZ4: V305 | DA4: V309 | DB4: V310 | DC4: V311 | DD4: V350 | DE4: V351 | DF4: V353 | DG4: V354 | DH4: V355 | DI4: V356 | DJ4: V357 | DK4: V358 | DL4: V359 | DM4: V360 | DN4: V362 | DO4: V363 | DP4: V365 | DQ4: V366 | DR4: V368 | DS4: V369 | DT4: V370 | DU4: V379 | DV4: V380 | DW4: V381 | DX4: V382 | DY4: V501 | DZ4: V502 | EA4: V503 | EB4: V504 | EC4: V505 | ED4: V506 | EE4: V507 | EF4: V508 | EG4: V509 | EH4: V510 | EI4: V511 | EJ4: V515 | EK4: V516 | EL4: V517 | EM4: V518 | EN4: V519 | EO4: V521 | EP4: V522 | EQ4: V523 | ER4: V524 | ES4: V525 | ET4: V526 | EU4: V528 | EV4: V529 | EW4: V531 | EX4: V532 | EY4: V533 | EZ4: V535 | FA4: V536 | FB4: V537 | FC4: V538 | FD4: V539 | FE4: V540 | FF4: V541 | FG4: V544 | FH4: V547 | FI4: V550 | FJ4: V551 | FK4: V552 | FL4: V553 | FM4: V554 | FN4: V555 | FO4: V556 | FP4: V557 | FQ4: V559 | FR4: V560 | FS4: V561 | FT4: V566 | FU4: V567 | FV4: V569 | FW4: V570 | FX4: V571 | FY4: V572 | FZ4: V574 | GA4: V584 | GB4: V590 | GC4: V591 | GD4: V592 | GE4: V593 | GF4: V594 | GG4: V595 | GH4: V596 | GI4: V597 | GJ4: V598 | GK4: V601 | GL4: V602 | GM4: V603 | GN4: V604 | GO4: V605 | GP4: V610 | GQ4: V701 | GR4: V702 | GS4: V711 | GT4: V712 | GU4: V750 | GV4: V801 | GW4: V900 | GX4: V904 | GY4: V905 | GZ4: V906 | HA4: V907 | HB4: V910 | HC4: V911 | HD4: V912 | HE4: V913 | HF4: V914 | HG4: V917 | HH4: V920 | HI4: V922
A5: PDC-R | B5: X | C5: Relay | D5: A0009821923 | E5: 1008695 | F5: V1 | G5: 60A | H5: X
A6: PDC-R | B6: F430 | C6: Fusible | D6: N000000008711 | E6: 1012169 | F6: V1 | G6: 15A | H6: X
A7: PDC-R | B7: F431 | C7: Fusible | D7: N000000008710 | E7: 1012170 | F7: V1 | G7: 10A | H7: X
A8: PDC-R | B8: F437 | C8: Fusible | D8: N000000008708 | E8: 1012166 | F8: V350 | G8: 5A | DD8: X
A9: PDC-R | B9: F441 | C9: Fusible | D9: N000000008709 | E9: 1012168 | F9: V584 | G9: 7.5A | GA9: X
A10: PDC-R | B10: F411 | C10: Fusible | D10: N000000008708 | E10: 1012166 | F10: V358 | G10: 5A | DK10: X
A11: PDC-R | B11: F454 | C11: Fusible | D11: N000000008704 | E11: 1012173 | F11: V133 | G11: 30A | BV11: X
A12: PDC-R | B12: F455 | C12: Fusible | D12: N000000008704 | E12: 1012173 | F12: V158 | G12: 30A | CH12: X
A13: PDC-R | B13: F447 | C13: Fusible | D13: N000000007659 | E13: 1012175 | F13: V900 | G13: 40A | GW13: X
A14: PDC-R | B14: F456 | C14: Fusible | D14: N000000008704 | E14: 1012173 | F14: V158 | G14: 30A | CH14: X
A15: PDC-R | B15: F457 | C15: Fusible | D15: N000000008703 | E15: 1012171 | F15: V544 | G15: 25A | FG15: X
A16: PDC-R | B16: F460 | C16: Fusible | D16: N000000008701 | E16: 1012172 | F16: V503 | G16: 15A | EA16: X
A17: PDC-R | B17: F461 | C17: Fusible | D17: N000000008704 | E17: 1012173 | F17: V190 | G17: 30A | CI17: X
A18: PDC-R | B18: T | C18: Relay | D18: A0025429419 | E18: 1010733 | F18: V1 | G18: 70A | H18: X
A19: PDC-R | B19: F432 | C19: Fusible | D19: N000000008709 | E19: 1012168 | F19: V1 | G19: 7.5A | H19: X
A20: PDC-R | B20: F442 | C20: Fusible | D20: N000000008708 | E20: 1012166 | F20: V561 | G20: 5A | FS20: X
A21: PDC-R | B21: F443 | C21: Fusible | D21: N000000008708 | E21: 1012166 | F21: V251 | G21: 5A | CQ21: X
A22: PDC-R | B22: F445 | C22: Fusible | D22: N000000008698 | E22: 1012177 | F22: V158 | G22: 5A | CH22: X
A23: PDC-R | B23: F419 | C23: Fusible | D23: N000000007659 | E23: 1012175 | F23: V49 | G23: 40A | AN23: X
A24: PDC-R | B24: F418 | C24: Fusible | D24: N000000007659 | E24: 1012175 | F24: V504 | G24: 40A | EB24: X
A25: PDC-R | B25: F413 | C25: Fusible | D25: N000000008704 | E25: 1012173 | F25: V1 | G25: 30A | H25: X
A26: PDC-R | B26: F414 | C26: Fusible | D26: N000000008704 | E26: 1012173 | F26: V152 | G26: 30A | CE26: X
A27: PDC-R | B27: F415 | C27: Fusible | D27: N000000008704 | E27: 1012173 | F27: V1 | G27: 30A | H27: X
A28: PDC-R | B28: F416 | C28: Fusible | D28: N000000008704 | E28: 1012173 | F28: V74/V75 | G28: 30A | AZ28: X | BA28: X
A29: PDC-R | B29: F417 | C29: Fusible | D29: N000000008704 | E29: 1012173 | F29: V74/V75 | G29: 30A | AZ29: X | BA29: X
A30: PDC-R | B30: F402 | C30: Fusible | D30: N000000008703 | E30: 1012171 | F30: V140 | G30: 25A | CC30: X
A31: PDC-R | B31: F421 | C31: Fusible | D31: N000000008704 | E31: 1012173 | F31: V1 | G31: 30A | H31: X
A32: PDC-R | B32: F424 | C32: Fusible | D32: N000000008704 | E32: 1012173 | F32: V253 | G32: 30A | CS32: X
A33: PDC-R | B33: F426 | C33: Fusible | D33: N000000008704 | E33: 1012173 | F33: V253 | G33: 30A | CS33: X
A34: PDC-R | B34: F447 | C34: Fusible | D34: N000000007659 | E34: 1012175 | F34: V900 | G34: 40A | GW34: X

Sheet Matriz Interior Izquierda F55
A3: Fusibles | H3: A2965401009 | I3: A2965402713 | J3: A2965400008 | K3: A2965409911 | L3: A2965404600 | M3: A2965404800 | N3: A2965405000 | O3: A2965405200 | P3: A2965405600 | Q3: A2965405400 | R3: A2965405800 | S3: A2965403914 | T3: A2965408818 | U3: A2965401108 | V3: A2965404014 | W3: A2965400213 | X3: A2965409812 | Y3: A2965407818 | Z3: A2965404114 | AA3: A2965404214 | AB3: A2965404314 | AC3: A2965404414 | AD3: A2965404514 | AE3: A2965404614 | AF3: A2965409412 | AG3: A2965404115 | AH3: A2965404215 | AI3: A2965405516 | AJ3: A2965405716 | AK3: A2965406615 | AL3: A2965406619 | AM3: A2965403113 | AN3: A2965402419 | AO3: A2965402109 | AP3: A2965403318 | AQ3: A2965404303 | AR3: A2965404703 | AS3: A2965404903 | AT3: A2965405103 | AU3: A2965406203 | AV3: A2965406503 | AW3: A2965406603 | AX3: A2965406703 | AY3: A2965407303 | AZ3: A2965407403 | BA3: A2965407703 | BB3: A2965408103 | BC3: A2965408503 | BD3: A2965408903 | BE3: A2965408514 | BF3: A2965403412 | BG3: A2965408214 | BH3: A2965406903 | BI3: A2965407903 | BJ3: A2965405314 | BK3: A2965400718 | BL3: A2965407618 | BM3: A2965400918 | BN3: A2965404619 | BO3: A2965406918 | BP3: A2965405614 | BQ3: A2965400613 | BR3: A2965400419 | BS3: A2965400219 | BT3: A2965401019 | BU3: A2965400619 | BV3: A2965400819 | BW3: A2965401219 | BX3: A2965407218 | BY3: A2965406513 | BZ3: A2965407614 | CA3: A2965406819 | CB3: A2965407113 | CC3: A2965407313 | CD3: A2965408504 | CE3: A2965400813 | CF3: A2965401314 | CG3: A2965405714 | CH3: A2965403518 | CI3: A2965409500 | CJ3: A2965409600 | CK3: A2965409700 | CL3: A2965409808 | CM3: A2965409208 | CN3: A2965409408 | CO3: A2965404914 | CP3: A2965409018 | CQ3: A2965402718 | CR3: A2965402918 | CS3: A2965404015 | CT3: A2965404419 | CU3: A2965408515 | CV3: A2965409314 | CW3: A2965401115 | CX3: A2965409114 | CY3: A2965409218 | CZ3: A2965405112 | DA3: A2965406516 | DB3: A2965406716 | DC3: A2965406814 | DD3: A2965407014 | DE3: A2965409418 | DF3: A2965409618 | DG3: A2965409818 | DH3: A2965400708 | DI3: A2965407114 | DJ3: A2965402908 | DK3: A2965406114 | DL3: A2965403108 | DM3: A2965404008 | DN3: A2965403112 | DO3: A2965406914 | DP3: A2965408914 | DQ3: A2965409514 | DR3: A2965407616 | DS3: A2965406614 | DT3: A2965406113 | DU3: A2965404113 | DV3: A2965404213 | DW3: A2965404313 | DX3: A2965402300 | DY3: A2965406415 | DZ3: A2965404719 | EA3: A2965404819 | EB3: A2965402700 | EC3: A2965402900 | ED3: A2965403100 | EE3: A2965404413 | EF3: A2965403400 | EG3: A2965405618 | EH3: A2965403700 | EI3: A2965405013 | EJ3: A2965405113 | EK3: A2965405213 | EL3: A2965403605 | EM3: A2965404218 | EN3: A2965404118 | EO3: A2965406418 | EP3: A2965404418 | EQ3: A2965407300 | ER3: A2965403918 | ES3: A2965407600 | ET3: A2965407700 | EU3: A2965407800 | EV3: A2965407900 | EW3: A2965408000 | EX3: A2965408100 | EY3: A2965408300 | EZ3: A2965407914 | FA3: A2965407216 | FB3: A2965403800 | FC3: A2965405018 | FD3: A2965404000 | FE3: A2965405218 | FF3: A2965404618 | FG3: A2965405418 | FH3: A2965404400 | FI3: A2965403705 | FJ3: A2965405313 | FK3: A2965406718 | FL3: A2965405413 | FM3: A2965407316 | FN3: A2965407416 | FO3: A2965409511 | FP3: A2965406618 | FQ3: A2965400101 | FR3: A2965409607 | FS3: A2965404013 | FT3: A2965409411 | FU3: A2965408911 | FV3: A2965408511 | FW3: A2965407911 | FX3: A2965406218 | FY3: A2965404818 | FZ3: A2965408111 | GA3: A2965408211 | GB3: A2965405014 | GC3: A2965404812 | GD3: A2965405214 | GE3: A2965405114 | GF3: A2965405012 | GG3: A2965407916 | GH3: A2965401113 | GI3: A2965401213 | GJ3: A2965403314 | GK3: A2965403414 | GL3: A2965401718 | GM3: A2965405914 | GN3: A2965406916 | GO3: A2965406312 | GP3: A2965400019 | GQ3: A2965406712 | GR3: A2965408712 | GS3: A2965406912 | GT3: A2965408912 | GU3: A2965408312 | GV3: A2965408512 | GW3: A2965407912 | GX3: A2965409112 | GY3: A2965407015 | GZ3: A2965406519 | HA3: =VLOOKUP(HA4,'Acomodos Modularidades'!$A$2:$B$211,2,FALSE) -> A2965408612 | HB3: =VLOOKUP(HB4,'Acomodos Modularidades'!$A$2:$B$211,2,FALSE) -> A2965406812 | HC3: =VLOOKUP(HC4,'Acomodos Modularidades'!$A$2:$B$211,2,FALSE) -> A2965408812 | HD3: =VLOOKUP(HD4,'Acomodos Modularidades'!$A$2:$B$211,2,FALSE) -> A2965408212 | HE3: =VLOOKUP(HE4,'Acomodos Modularidades'!$A$2:$B$211,2,FALSE) -> A2965408412 | HF3: =VLOOKUP(HF4,'Acomodos Modularidades'!$A$2:$B$211,2,FALSE) -> A2965407812 | HG3: =VLOOKUP(HG4,'Acomodos Modularidades'!$A$2:$B$211,2,FALSE) -> A2965409012 | HH3: =VLOOKUP(HH4,'Acomodos Modularidades'!$A$2:$B$211,2,FALSE) -> A2965406915 | HI3: =VLOOKUP(HI4,'Acomodos Modularidades'!$A$2:$B$211,2,FALSE) -> A2965406419
A4: Subensamble | B4: kurzname | C4: Descripcion | D4: # Mercedez | E4: Oracle (s) | F4: Variante | G4: Amp | H4: V1 | I4: V2 | J4: V6 | K4: V8 | L4: V9 | M4: V10 | N4: V11 | O4: V12 | P4: V13 | Q4: V14 | R4: V15 | S4: V16 | T4: V17 | U4: V18 | V4: V19 | W4: V20 | X4: V23 | Y4: V26 | Z4: V29 | AA4: V30 | AB4: V31 | AC4: V32 | AD4: V33 | AE4: V34 | AF4: V38 | AG4: V41 | AH4: V42 | AI4: V43 | AJ4: V44 | AK4: V45 | AL4: V46 | AM4: V48 | AN4: V49 | AO4: V50 | AP4: V51 | AQ4: V60 | AR4: V62 | AS4: V63 | AT4: V65 | AU4: V68 | AV4: V69 | AW4: V70 | AX4: V71 | AY4: V73 | AZ4: V74 | BA4: V75 | BB4: V76 | BC4: V77 | BD4: V79 | BE4: V81 | BF4: V83 | BG4: V86 | BH4: V89 | BI4: V91 | BJ4: V93 | BK4: V94 | BL4: V96 | BM4: V97 | BN4: V100 | BO4: V102 | BP4: V103 | BQ4: V105 | BR4: V106 | BS4: V110 | BT4: V111 | BU4: V132 | BV4: V133 | BW4: V134 | BX4: V135 | BY4: V136 | BZ4: V137 | CA4: V138 | CB4: V139 | CC4: V140 | CD4: V151 | CE4: V152 | CF4: V155 | CG4: V157 | CH4: V158 | CI4: V190 | CJ4: V200 | CK4: V215 | CL4: V218 | CM4: V240 | CN4: V241 | CO4: V242 | CP4: V243 | CQ4: V251 | CR4: V252 | CS4: V253 | CT4: V254 | CU4: V255 | CV4: V256 | CW4: V257 | CX4: V258 | CY4: V259 | CZ4: V305 | DA4: V309 | DB4: V310 | DC4: V311 | DD4: V350 | DE4: V351 | DF4: V353 | DG4: V354 | DH4: V355 | DI4: V356 | DJ4: V357 | DK4: V358 | DL4: V359 | DM4: V360 | DN4: V362 | DO4: V363 | DP4: V365 | DQ4: V366 | DR4: V368 | DS4: V369 | DT4: V370 | DU4: V379 | DV4: V380 | DW4: V381 | DX4: V382 | DY4: V501 | DZ4: V502 | EA4: V503 | EB4: V504 | EC4: V505 | ED4: V506 | EE4: V507 | EF4: V508 | EG4: V509 | EH4: V510 | EI4: V511 | EJ4: V515 | EK4: V516 | EL4: V517 | EM4: V518 | EN4: V519 | EO4: V521 | EP4: V522 | EQ4: V523 | ER4: V524 | ES4: V525 | ET4: V526 | EU4: V528 | EV4: V529 | EW4: V531 | EX4: V532 | EY4: V533 | EZ4: V535 | FA4: V536 | FB4: V537 | FC4: V538 | FD4: V539 | FE4: V540 | FF4: V541 | FG4: V544 | FH4: V547 | FI4: V550 | FJ4: V551 | FK4: V552 | FL4: V553 | FM4: V554 | FN4: V555 | FO4: V556 | FP4: V557 | FQ4: V559 | FR4: V560 | FS4: V561 | FT4: V566 | FU4: V567 | FV4: V569 | FW4: V570 | FX4: V571 | FY4: V572 | FZ4: V574 | GA4: V584 | GB4: V590 | GC4: V591 | GD4: V592 | GE4: V593 | GF4: V594 | GG4: V595 | GH4: V596 | GI4: V597 | GJ4: V598 | GK4: V601 | GL4: V602 | GM4: V603 | GN4: V604 | GO4: V605 | GP4: V610 | GQ4: V701 | GR4: V702 | GS4: V711 | GT4: V712 | GU4: V750 | GV4: V801 | GW4: V900 | GX4: V904 | GY4: V905 | GZ4: V906 | HA4: V907 | HB4: V910 | HC4: V911 | HD4: V912 | HE4: V913 | HF4: V914 | HG4: V917 | HH4: V920 | HI4: V922
A5: Fuse Box F55 | B5: 1A | C5: Fusible | D5: N000000004204 | E5: 1012179 | F5: V900 | G5: 10A | GW5: X
A6: Fuse Box F55 | B6: 2A | C6: Fusible | D6: N000000004202 | E6: 1012180 | F6: V900 | G6: 5A | GW6: X
A7: Fuse Box F55 | B7: 3A | C7: Fusible | D7: N000000004204 | E7: 1012179 | F7: V900 | G7: 10A | GW7: X
A8: Fuse Box F55 | B8: 4A | C8: Fusible | D8: N000000004204 | E8: 1012179 | F8: V900 | G8: 10A | GW8: X
A9: Fuse Box F55 | B9: 5A | C9: Fusible | D9: N000000004204 | E9: 1012179 | F9: V900 | G9: 10A | GW9: X
A10: Fuse Box F55 | B10: 7A | C10: Fusible | D10: N000000004202 | E10: 1012180 | F10: V900 | G10: 5A | GW10: X

Sheet MFB-P1
A3: Fusibles | J3: A2965401009 | K3: A2965402713 | L3: A2965400008 | M3: A2965409911 | N3: A2965404600 | O3: A2965404800 | P3: A2965405000 | Q3: A2965405200 | R3: A2965405600 | S3: A2965405400 | T3: A2965405800 | U3: A2965403914 | V3: A2965408818 | W3: A2965401108 | X3: A2965404014 | Y3: A2965400213 | Z3: A2965409812 | AA3: A2965407818 | AB3: A2965404114 | AC3: A2965404214 | AD3: A2965404314 | AE3: A2965404414 | AF3: A2965404514 | AG3: A2965404614 | AH3: A2965409412 | AI3: A2965404115 | AJ3: A2965404215 | AK3: A2965405516 | AL3: A2965405716 | AM3: A2965406615 | AN3: A2965406619 | AO3: A2965403113 | AP3: A2965402419 | AQ3: A2965402109 | AR3: A2965403318 | AS3: A2965404303 | AT3: A2965404703 | AU3: A2965404903 | AV3: A2965405103 | AW3: A2965406203 | AX3: A2965406503 | AY3: A2965406603 | AZ3: A2965406703 | BA3: A2965407303 | BB3: A2965407403 | BC3: A2965407703 | BD3: A2965408103 | BE3: A2965408503 | BF3: A2965408903 | BG3: A2965408514 | BH3: A2965403412 | BI3: A2965408214 | BJ3: A2965406903 | BK3: A2965407903 | BL3: A2965405314 | BM3: A2965400718 | BN3: A2965407618 | BO3: A2965400918 | BP3: A2965404619 | BQ3: A2965406918 | BR3: A2965405614 | BS3: A2965400613 | BT3: A2965400419 | BU3: A2965400219 | BV3: A2965401019 | BW3: A2965400619 | BX3: A2965400819 | BY3: A2965401219 | BZ3: A2965407218 | CA3: A2965406513 | CB3: A2965407614 | CC3: A2965406819 | CD3: A2965407113 | CE3: A2965407313 | CF3: A2965408504 | CG3: A2965400813 | CH3: A2965401314 | CI3: A2965405714 | CJ3: A2965403518 | CK3: A2965409500 | CL3: A2965409600 | CM3: A2965409700 | CN3: A2965409808 | CO3: A2965409208 | CP3: A2965409408 | CQ3: A2965404914 | CR3: A2965409018 | CS3: A2965402718 | CT3: A2965402918 | CU3: A2965404015 | CV3: A2965404419 | CW3: A2965408515 | CX3: A2965409314 | CY3: A2965401115 | CZ3: A2965409114 | DA3: A2965409218 | DB3: A2965405112 | DC3: A2965406516 | DD3: A2965406716 | DE3: A2965406814 | DF3: A2965407014 | DG3: A2965409418 | DH3: A2965409618 | DI3: A2965409818 | DJ3: A2965400708 | DK3: A2965407114 | DL3: A2965402908 | DM3: A2965406114 | DN3: A2965403108 | DO3: A2965404008 | DP3: A2965403112 | DQ3: A2965406914 | DR3: A2965408914 | DS3: A2965409514 | DT3: A2965407616 | DU3: A2965406614 | DV3: A2965406113 | DW3: A2965404113 | DX3: A2965404213 | DY3: A2965404313 | DZ3: A2965402300 | EA3: A2965406415 | EB3: A2965404719 | EC3: A2965404819 | ED3: A2965402700 | EE3: A2965402900 | EF3: A2965403100 | EG3: A2965404413 | EH3: A2965403400 | EI3: A2965405618 | EJ3: A2965403700 | EK3: A2965405013 | EL3: A2965405113 | EM3: A2965405213 | EN3: A2965403605 | EO3: A2965404218 | EP3: A2965404118 | EQ3: A2965406418 | ER3: A2965404418 | ES3: A2965407300 | ET3: A2965403918 | EU3: A2965407600 | EV3: A2965407700 | EW3: A2965407800 | EX3: A2965407900 | EY3: A2965408000 | EZ3: A2965408100 | FA3: A2965408300 | FB3: A2965407914 | FC3: A2965407216 | FD3: A2965403800 | FE3: A2965405018 | FF3: A2965404000 | FG3: A2965405218 | FH3: A2965404618 | FI3: A2965405418 | FJ3: A2965404400 | FK3: A2965403705 | FL3: A2965405313 | FM3: A2965406718 | FN3: A2965405413 | FO3: A2965407316 | FP3: A2965407416 | FQ3: A2965409511 | FR3: A2965406618 | FS3: A2965400101 | FT3: A2965409607 | FU3: A2965404013 | FV3: A2965409411 | FW3: A2965408911 | FX3: A2965408511 | FY3: A2965407911 | FZ3: A2965406218 | GA3: A2965404818 | GB3: A2965408111 | GC3: A2965408211 | GD3: A2965405014 | GE3: A2965404812 | GF3: A2965405214 | GG3: A2965405114 | GH3: A2965405012 | GI3: A2965407916 | GJ3: A2965401113 | GK3: A2965401213 | GL3: A2965403314 | GM3: A2965403414 | GN3: A2965401718 | GO3: A2965405914 | GP3: A2965406916 | GQ3: A2965406312 | GR3: A2965400019 | GS3: A2965406712 | GT3: A2965408712 | GU3: A2965406912 | GV3: A2965408912 | GW3: A2965408312 | GX3: A2965408512 | GY3: A2965407912 | GZ3: A2965409112 | HA3: A2965407015 | HB3: A2965406519 | HC3: =VLOOKUP(HC4,'Acomodos Modularidades'!$A$2:$B$211,2,FALSE) -> A2965408612 | HD3: =VLOOKUP(HD4,'Acomodos Modularidades'!$A$2:$B$211,2,FALSE) -> A2965406812 | HE3: =VLOOKUP(HE4,'Acomodos Modularidades'!$A$2:$B$211,2,FALSE) -> A2965408812 | HF3: =VLOOKUP(HF4,'Acomodos Modularidades'!$A$2:$B$211,2,FALSE) -> A2965408212 | HG3: =VLOOKUP(HG4,'Acomodos Modularidades'!$A$2:$B$211,2,FALSE) -> A2965408412 | HH3: =VLOOKUP(HH4,'Acomodos Modularidades'!$A$2:$B$211,2,FALSE) -> A2965407812 | HI3: =VLOOKUP(HI4,'Acomodos Modularidades'!$A$2:$B$211,2,FALSE) -> A2965409012 | HJ3: =VLOOKUP(HJ4,'Acomodos Modularidades'!$A$2:$B$211,2,FALSE) -> A2965406915 | HK3: =VLOOKUP(HK4,'Acomodos Modularidades'!$A$2:$B$211,2,FALSE) -> A2965406419
A4: Subensamble | B4: kurzname | C4: Descripcion | D4: Kurzname | E4: # Mercedez | F4: Oracle de Terminal | G4: # Mercedes Tuerca | H4: Oracle (s) | I4: Variante | J4: V1 | K4: V2 | L4: V6 | M4: V8 | N4: V9 | O4: V10 | P4: V11 | Q4: V12 | R4: V13 | S4: V14 | T4: V15 | U4: V16 | V4: V17 | W4: V18 | X4: V19 | Y4: V20 | Z4: V23 | AA4: V26 | AB4: V29 | AC4: V30 | AD4: V31 | AE4: V32 | AF4: V33 | AG4: V34 | AH4: V38 | AI4: V41 | AJ4: V42 | AK4: V43 | AL4: V44 | AM4: V45 | AN4: V46 | AO4: V48 | AP4: V49 | AQ4: V50 | AR4: V51 | AS4: V60 | AT4: V62 | AU4: V63 | AV4: V65 | AW4: V68 | AX4: V69 | AY4: V70 | AZ4: V71 | BA4: V73 | BB4: V74 | BC4: V75 | BD4: V76 | BE4: V77 | BF4: V79 | BG4: V81 | BH4: V83 | BI4: V86 | BJ4: V89 | BK4: V91 | BL4: V93 | BM4: V94 | BN4: V96 | BO4: V97 | BP4: V100 | BQ4: V102 | BR4: V103 | BS4: V105 | BT4: V106 | BU4: V110 | BV4: V111 | BW4: V132 | BX4: V133 | BY4: V134 | BZ4: V135 | CA4: V136 | CB4: V137 | CC4: V138 | CD4: V139 | CE4: V140 | CF4: V151 | CG4: V152 | CH4: V155 | CI4: V157 | CJ4: V158 | CK4: V190 | CL4: V200 | CM4: V215 | CN4: V218 | CO4: V240 | CP4: V241 | CQ4: V242 | CR4: V243 | CS4: V251 | CT4: V252 | CU4: V253 | CV4: V254 | CW4: V255 | CX4: V256 | CY4: V257 | CZ4: V258 | DA4: V259 | DB4: V305 | DC4: V309 | DD4: V310 | DE4: V311 | DF4: V350 | DG4: V351 | DH4: V353 | DI4: V354 | DJ4: V355 | DK4: V356 | DL4: V357 | DM4: V358 | DN4: V359 | DO4: V360 | DP4: V362 | DQ4: V363 | DR4: V365 | DS4: V366 | DT4: V368 | DU4: V369 | DV4: V370 | DW4: V379 | DX4: V380 | DY4: V381 | DZ4: V382 | EA4: V501 | EB4: V502 | EC4: V503 | ED4: V504 | EE4: V505 | EF4: V506 | EG4: V507 | EH4: V508 | EI4: V509 | EJ4: V510 | EK4: V511 | EL4: V515 | EM4: V516 | EN4: V517 | EO4: V518 | EP4: V519 | EQ4: V521 | ER4: V522 | ES4: V523 | ET4: V524 | EU4: V525 | EV4: V526 | EW4: V528 | EX4: V529 | EY4: V531 | EZ4: V532 | FA4: V533 | FB4: V535 | FC4: V536 | FD4: V537 | FE4: V538 | FF4: V539 | FG4: V540 | FH4: V541 | FI4: V544 | FJ4: V547 | FK4: V550 | FL4: V551 | FM4: V552 | FN4: V553 | FO4: V554 | FP4: V555 | FQ4: V556 | FR4: V557 | FS4: V559 | FT4: V560 | FU4: V561 | FV4: V566 | FW4: V567 | FX4: V569 | FY4: V570 | FZ4: V571 | GA4: V572 | GB4: V574 | GC4: V584 | GD4: V590 | GE4: V591 | GF4: V592 | GG4: V593 | GH4: V594 | GI4: V595 | GJ4: V596 | GK4: V597 | GL4: V598 | GM4: V601 | GN4: V602 | GO4: V603 | GP4: V604 | GQ4: V605 | GR4: V610 | GS4: V701 | GT4: V702 | GU4: V711 | GV4: V712 | GW4: V750 | GX4: V801 | GY4: V900 | GZ4: V904 | HA4: V905 | HB4: V906 | HC4: V907 | HD4: V910 | HE4: V911 | HF4: V912 | HG4: V913 | HH4: V914 | HI4: V917 | HJ4: V920 | HK4: V922
A5: MFB-P1 | B5: A41 | C5: Torque | D5: F150/6*A41-K | E5: A1679821600 | F5: 1008205 | G5: N000000008271 | H5: 1013224 | I5: V49 | AP5: X
A6: MFB-P1 | B6: A42 | C6: Torque | D6: F150/6*A42-K | E6: A0009823203 | F6: 1008215 | G6: N000000008272 | H6: 1013225 | I6: V49 | AP6: X
A7: MFB-P1 | B7: A43 | C7: Torque | D7: F150/6*A43-K | E7: A0009823603 | F7: 1008212 | G7: N000000008272 | H7: 1013225 | I7: V49 | AP7: X
A8: MFB-P1 | B8: A44 | C8: Torque | D8: F150/6*A44-K | F8: - | I8: -
A9: MFB-P1 | B9: A45 | C9: Torque | D9: F150/6*A45-K | E9: A1679821100 | F9: 1008213 | G9: N000000008272 | H9: 1013225 | I9: V218 | CN9: X
A10: MFB-P1 | B10: A46 | C10: Torque | D10: F150/6*A46-K | E10: A1679821000 | F10: 1008223 | G10: N000000008271 | H10: 1013224 | I10: V49 | AP10: X
A11: MFB-P1 | B11: A47 | C11: Torque | D11: F150/6*A47-K | F11: - | I11: -

Sheet MFB-P2
A3: Fusibles | J3: A2965401009 | K3: A2965402713 | L3: A2965400008 | M3: A2965409911 | N3: A2965404600 | O3: A2965404800 | P3: A2965405000 | Q3: A2965405200 | R3: A2965405600 | S3: A2965405400 | T3: A2965405800 | U3: A2965403914 | V3: A2965408818 | W3: A2965401108 | X3: A2965404014 | Y3: A2965400213 | Z3: A2965409812 | AA3: A2965407818 | AB3: A2965404114 | AC3: A2965404214 | AD3: A2965404314 | AE3: A2965404414 | AF3: A2965404514 | AG3: A2965404614 | AH3: A2965409412 | AI3: A2965404115 | AJ3: A2965404215 | AK3: A2965405516 | AL3: A2965405716 | AM3: A2965406615 | AN3: A2965406619 | AO3: A2965403113 | AP3: A2965402419 | AQ3: A2965402109 | AR3: A2965403318 | AS3: A2965404303 | AT3: A2965404703 | AU3: A2965404903 | AV3: A2965405103 | AW3: A2965406203 | AX3: A2965406503 | AY3: A2965406603 | AZ3: A2965406703 | BA3: A2965407303 | BB3: A2965407403 | BC3: A2965407703 | BD3: A2965408103 | BE3: A2965408503 | BF3: A2965408903 | BG3: A2965408514 | BH3: A2965403412 | BI3: A2965408214 | BJ3: A2965406903 | BK3: A2965407903 | BL3: A2965405314 | BM3: A2965400718 | BN3: A2965407618 | BO3: A2965400918 | BP3: A2965404619 | BQ3: A2965406918 | BR3: A2965405614 | BS3: A2965400613 | BT3: A2965400419 | BU3: A2965400219 | BV3: A2965401019 | BW3: A2965400619 | BX3: A2965400819 | BY3: A2965401219 | BZ3: A2965407218 | CA3: A2965406513 | CB3: A2965407614 | CC3: A2965406819 | CD3: A2965407113 | CE3: A2965407313 | CF3: A2965408504 | CG3: A2965400813 | CH3: A2965401314 | CI3: A2965405714 | CJ3: A2965403518 | CK3: A2965409500 | CL3: A2965409600 | CM3: A2965409700 | CN3: A2965409808 | CO3: A2965409208 | CP3: A2965409408 | CQ3: A2965404914 | CR3: A2965409018 | CS3: A2965402718 | CT3: A2965402918 | CU3: A2965404015 | CV3: A2965404419 | CW3: A2965408515 | CX3: A2965409314 | CY3: A2965401115 | CZ3: A2965409114 | DA3: A2965409218 | DB3: A2965405112 | DC3: A2965406516 | DD3: A2965406716 | DE3: A2965406814 | DF3: A2965407014 | DG3: A2965409418 | DH3: A2965409618 | DI3: A2965409818 | DJ3: A2965400708 | DK3: A2965407114 | DL3: A2965402908 | DM3: A2965406114 | DN3: A2965403108 | DO3: A2965404008 | DP3: A2965403112 | DQ3: A2965406914 | DR3: A2965408914 | DS3: A2965409514 | DT3: A2965407616 | DU3: A2965406614 | DV3: A2965406113 | DW3: A2965404113 | DX3: A2965404213 | DY3: A2965404313 | DZ3: A2965402300 | EA3: A2965406415 | EB3: A2965404719 | EC3: A2965404819 | ED3: A2965402700 | EE3: A2965402900 | EF3: A2965403100 | EG3: A2965404413 | EH3: A2965403400 | EI3: A2965405618 | EJ3: A2965403700 | EK3: A2965405013 | EL3: A2965405113 | EM3: A2965405213 | EN3: A2965403605 | EO3: A2965404218 | EP3: A2965404118 | EQ3: A2965406418 | ER3: A2965404418 | ES3: A2965407300 | ET3: A2965403918 | EU3: A2965407600 | EV3: A2965407700 | EW3: A2965407800 | EX3: A2965407900 | EY3: A2965408000 | EZ3: A2965408100 | FA3: A2965408300 | FB3: A2965407914 | FC3: A2965407216 | FD3: A2965403800 | FE3: A2965405018 | FF3: A2965404000 | FG3: A2965405218 | FH3: A2965404618 | FI3: A2965405418 | FJ3: A2965404400 | FK3: A2965403705 | FL3: A2965405313 | FM3: A2965406718 | FN3: A2965405413 | FO3: A2965407316 | FP3: A2965407416 | FQ3: A2965409511 | FR3: A2965406618 | FS3: A2965400101 | FT3: A2965409607 | FU3: A2965404013 | FV3: A2965409411 | FW3: A2965408911 | FX3: A2965408511 | FY3: A2965407911 | FZ3: A2965406218 | GA3: A2965404818 | GB3: A2965408111 | GC3: A2965408211 | GD3: A2965405014 | GE3: A2965404812 | GF3: A2965405214 | GG3: A2965405114 | GH3: A2965405012 | GI3: A2965407916 | GJ3: A2965401113 | GK3: A2965401213 | GL3: A2965403314 | GM3: A2965403414 | GN3: A2965401718 | GO3: A2965405914 | GP3: A2965406916 | GQ3: A2965406312 | GR3: A2965400019 | GS3: A2965406712 | GT3: A2965408712 | GU3: A2965406912 | GV3: A2965408912 | GW3: A2965408312 | GX3: A2965408512 | GY3: A2965407912 | GZ3: A2965409112 | HA3: A2965407015 | HB3: A2965406519 | HC3: =VLOOKUP(HC4,'Acomodos Modularidades'!$A$2:$B$211,2,FALSE) -> A2965408612 | HD3: =VLOOKUP(HD4,'Acomodos Modularidades'!$A$2:$B$211,2,FALSE) -> A2965406812 | HE3: =VLOOKUP(HE4,'Acomodos Modularidades'!$A$2:$B$211,2,FALSE) -> A2965408812 | HF3: =VLOOKUP(HF4,'Acomodos Modularidades'!$A$2:$B$211,2,FALSE) -> A2965408212 | HG3: =VLOOKUP(HG4,'Acomodos Modularidades'!$A$2:$B$211,2,FALSE) -> A2965408412 | HH3: =VLOOKUP(HH4,'Acomodos Modularidades'!$A$2:$B$211,2,FALSE) -> A2965407812 | HI3: =VLOOKUP(HI4,'Acomodos Modularidades'!$A$2:$B$211,2,FALSE) -> A2965409012 | HJ3: =VLOOKUP(HJ4,'Acomodos Modularidades'!$A$2:$B$211,2,FALSE) -> A2965406915 | HK3: =VLOOKUP(HK4,'Acomodos Modularidades'!$A$2:$B$211,2,FALSE) -> A2965406419
A4: Subensamble | B4: kurzname | C4: Descripcion | D4: Kurzname | E4: # Mercedez | F4: Oracle de Terminal | G4: # Mercede Tuerca | H4: Oracle (s) | I4: Variante | J4: V1 | K4: V2 | L4: V6 | M4: V8 | N4: V9 | O4: V10 | P4: V11 | Q4: V12 | R4: V13 | S4: V14 | T4: V15 | U4: V16 | V4: V17 | W4: V18 | X4: V19 | Y4: V20 | Z4: V23 | AA4: V26 | AB4: V29 | AC4: V30 | AD4: V31 | AE4: V32 | AF4: V33 | AG4: V34 | AH4: V38 | AI4: V41 | AJ4: V42 | AK4: V43 | AL4: V44 | AM4: V45 | AN4: V46 | AO4: V48 | AP4: V49 | AQ4: V50 | AR4: V51 | AS4: V60 | AT4: V62 | AU4: V63 | AV4: V65 | AW4: V68 | AX4: V69 | AY4: V70 | AZ4: V71 | BA4: V73 | BB4: V74 | BC4: V75 | BD4: V76 | BE4: V77 | BF4: V79 | BG4: V81 | BH4: V83 | BI4: V86 | BJ4: V89 | BK4: V91 | BL4: V93 | BM4: V94 | BN4: V96 | BO4: V97 | BP4: V100 | BQ4: V102 | BR4: V103 | BS4: V105 | BT4: V106 | BU4: V110 | BV4: V111 | BW4: V132 | BX4: V133 | BY4: V134 | BZ4: V135 | CA4: V136 | CB4: V137 | CC4: V138 | CD4: V139 | CE4: V140 | CF4: V151 | CG4: V152 | CH4: V155 | CI4: V157 | CJ4: V158 | CK4: V190 | CL4: V200 | CM4: V215 | CN4: V218 | CO4: V240 | CP4: V241 | CQ4: V242 | CR4: V243 | CS4: V251 | CT4: V252 | CU4: V253 | CV4: V254 | CW4: V255 | CX4: V256 | CY4: V257 | CZ4: V258 | DA4: V259 | DB4: V305 | DC4: V309 | DD4: V310 | DE4: V311 | DF4: V350 | DG4: V351 | DH4: V353 | DI4: V354 | DJ4: V355 | DK4: V356 | DL4: V357 | DM4: V358 | DN4: V359 | DO4: V360 | DP4: V362 | DQ4: V363 | DR4: V365 | DS4: V366 | DT4: V368 | DU4: V369 | DV4: V370 | DW4: V379 | DX4: V380 | DY4: V381 | DZ4: V382 | EA4: V501 | EB4: V502 | EC4: V503 | ED4: V504 | EE4: V505 | EF4: V506 | EG4: V507 | EH4: V508 | EI4: V509 | EJ4: V510 | EK4: V511 | EL4: V515 | EM4: V516 | EN4: V517 | EO4: V518 | EP4: V519 | EQ4: V521 | ER4: V522 | ES4: V523 | ET4: V524 | EU4: V525 | EV4: V526 | EW4: V528 | EX4: V529 | EY4: V531 | EZ4: V532 | FA4: V533 | FB4: V535 | FC4: V536 | FD4: V537 | FE4: V538 | FF4: V539 | FG4: V540 | FH4: V541 | FI4: V544 | FJ4: V547 | FK4: V550 | FL4: V551 | FM4: V552 | FN4: V553 | FO4: V554 | FP4: V555 | FQ4: V556 | FR4: V557 | FS4: V559 | FT4: V560 | FU4: V561 | FV4: V566 | FW4: V567 | FX4: V569 | FY4: V570 | FZ4: V571 | GA4: V572 | GB4: V574 | GC4: V584 | GD4: V590 | GE4: V591 | GF4: V592 | GG4: V593 | GH4: V594 | GI4: V595 | GJ4: V596 | GK4: V597 | GL4: V598 | GM4: V601 | GN4: V602 | GO4: V603 | GP4: V604 | GQ4: V605 | GR4: V610 | GS4: V701 | GT4: V702 | GU4: V711 | GV4: V712 | GW4: V750 | GX4: V801 | GY4: V900 | GZ4: V904 | HA4: V905 | HB4: V906 | HC4: V907 | HD4: V910 | HE4: V911 | HF4: V912 | HG4: V913 | HH4: V914 | HI4: V917 | HJ4: V920 | HK4: V922
A5: MFB-P2 | B5: A20 | C5: Torque | D5: F150/7*A20-K | E5: A1679821600 | F5: 1008205 | G5: N000000008271 | H5: 1013224 | I5: V49 | AP5: X
A6: MFB-P2 | B6: A21 | C6: Torque | D6: F150/7*A21-K | E6: A0009823703 | F6: 1008216 | G6: N000000008272 | H6: 1013225 | I6: V49 | AP6: X
A7: MFB-P2 | B7: A22 | C7: Torque | D7: F150/7*A22-K | E7: A1679821500 | F7: 1008218 | G7: N000000008272 | H7: 1013225 | I7: V1 | J7: X
A8: MFB-P2 | B8: A23 | C8: Torque | D8: F150/7*A23-K | E8: A0009822403 | F8: 1008210 | G8: N000000008272 | H8: 1013225 | I8: V305 | DB8: X
A9: MFB-P2 | B9: A24 | C9: Torque | D9: F150/7*A24-K | E9: A0009822703 | F9: 1008211 | G9: N000000008272 | H9: 1013225 | I9: V49 | AP9: X
A10: MFB-P2 | B10: A25 | C10: Torque | D10: F150/7*A25-K | E10: A0009826203 | F10: 1008221 | G10: N000000008272 | H10: 1013224 | I10: V49 | AP10: X
A11: MFB-P2 | B11: A26 | C11: Torque | D11: F150/7*A26-K | E11: A0009823203 | F11: 1008215 | G11: N000000008272 | H11: 1013225 | I11: V311 | DE11: X
A12: MFB-P2 | B12: A27 | C12: Torque | D12: F150/7*A27-K | E12: A0009823603 | F12: 1008212 | G12: N000000008272 | H12: 1013225 | I12: V365 | DR12: X
A13: MFB-P2 | B13: A28 | C13: Torque | D13: F150/7*A28-K | E13: A0009821703 | F13: 1008421 | G13: N000000008272 | H13: 1013225 | I13: V900 | GY13: X
A14: MFB-P2 | B14: A29 | C14: Torque | D14: F150/7*A29-K | E14: A0009821411 | F14: 1008448 | G14: N000000008272 | H14: 1013225 | I14: V311 | DE14: X
A15: MFB-P2 | B15: A30 | C15: Torque | D15: F150/7*A30-K | E15: A1679820500 | F15: 1008222 | G15: N000000008271 | H15: 1013224 | I15: V49 | AP15: X

Sheet MFB-S
A3: Fusibles | J3: A2965401009 | K3: A2965402713 | L3: A2965400008 | M3: A2965409911 | N3: A2965404600 | O3: A2965404800 | P3: A2965405000 | Q3: A2965405200 | R3: A2965405600 | S3: A2965405400 | T3: A2965405800 | U3: A2965403914 | V3: A2965408818 | W3: A2965401108 | X3: A2965404014 | Y3: A2965400213 | Z3: A2965409812 | AA3: A2965407818 | AB3: A2965404114 | AC3: A2965404214 | AD3: A2965404314 | AE3: A2965404414 | AF3: A2965404514 | AG3: A2965404614 | AH3: A2965409412 | AI3: A2965404115 | AJ3: A2965404215 | AK3: A2965405516 | AL3: A2965405716 | AM3: A2965406615 | AN3: A2965406619 | AO3: A2965403113 | AP3: A2965402419 | AQ3: A2965402109 | AR3: A2965403318 | AS3: A2965404303 | AT3: A2965404703 | AU3: A2965404903 | AV3: A2965405103 | AW3: A2965406203 | AX3: A2965406503 | AY3: A2965406603 | AZ3: A2965406703 | BA3: A2965407303 | BB3: A2965407403 | BC3: A2965407703 | BD3: A2965408103 | BE3: A2965408503 | BF3: A2965408903 | BG3: A2965408514 | BH3: A2965403412 | BI3: A2965408214 | BJ3: A2965406903 | BK3: A2965407903 | BL3: A2965405314 | BM3: A2965400718 | BN3: A2965407618 | BO3: A2965400918 | BP3: A2965404619 | BQ3: A2965406918 | BR3: A2965405614 | BS3: A2965400613 | BT3: A2965400419 | BU3: A2965400219 | BV3: A2965401019 | BW3: A2965400619 | BX3: A2965400819 | BY3: A2965401219 | BZ3: A2965407218 | CA3: A2965406513 | CB3: A2965407614 | CC3: A2965406819 | CD3: A2965407113 | CE3: A2965407313 | CF3: A2965408504 | CG3: A2965400813 | CH3: A2965401314 | CI3: A2965405714 | CJ3: A2965403518 | CK3: A2965409500 | CL3: A2965409600 | CM3: A2965409700 | CN3: A2965409808 | CO3: A2965409208 | CP3: A2965409408 | CQ3: A2965404914 | CR3: A2965409018 | CS3: A2965402718 | CT3: A2965402918 | CU3: A2965404015 | CV3: A2965404419 | CW3: A2965408515 | CX3: A2965409314 | CY3: A2965401115 | CZ3: A2965409114 | DA3: A2965409218 | DB3: A2965405112 | DC3: A2965406516 | DD3: A2965406716 | DE3: A2965406814 | DF3: A2965407014 | DG3: A2965409418 | DH3: A2965409618 | DI3: A2965409818 | DJ3: A2965400708 | DK3: A2965407114 | DL3: A2965402908 | DM3: A2965406114 | DN3: A2965403108 | DO3: A2965404008 | DP3: A2965403112 | DQ3: A2965406914 | DR3: A2965408914 | DS3: A2965409514 | DT3: A2965407616 | DU3: A2965406614 | DV3: A2965406113 | DW3: A2965404113 | DX3: A2965404213 | DY3: A2965404313 | DZ3: A2965402300 | EA3: A2965406415 | EB3: A2965404719 | EC3: A2965404819 | ED3: A2965402700 | EE3: A2965402900 | EF3: A2965403100 | EG3: A2965404413 | EH3: A2965403400 | EI3: A2965405618 | EJ3: A2965403700 | EK3: A2965405013 | EL3: A2965405113 | EM3: A2965405213 | EN3: A2965403605 | EO3: A2965404218 | EP3: A2965404118 | EQ3: A2965406418 | ER3: A2965404418 | ES3: A2965407300 | ET3: A2965403918 | EU3: A2965407600 | EV3: A2965407700 | EW3: A2965407800 | EX3: A2965407900 | EY3: A2965408000 | EZ3: A2965408100 | FA3: A2965408300 | FB3: A2965407914 | FC3: A2965407216 | FD3: A2965403800 | FE3: A2965405018 | FF3: A2965404000 | FG3: A2965405218 | FH3: A2965404618 | FI3: A2965405418 | FJ3: A2965404400 | FK3: A2965403705 | FL3: A2965405313 | FM3: A2965406718 | FN3: A2965405413 | FO3: A2965407316 | FP3: A2965407416 | FQ3: A2965409511 | FR3: A2965406618 | FS3: A2965400101 | FT3: A2965409607 | FU3: A2965404013 | FV3: A2965409411 | FW3: A2965408911 | FX3: A2965408511 | FY3: A2965407911 | FZ3: A2965406218 | GA3: A2965404818 | GB3: A2965408111 | GC3: A2965408211 | GD3: A2965405014 | GE3: A2965404812 | GF3: A2965405214 | GG3: A2965405114 | GH3: A2965405012 | GI3: A2965407916 | GJ3: A2965401113 | GK3: A2965401213 | GL3: A2965403314 | GM3: A2965403414 | GN3: A2965401718 | GO3: A2965405914 | GP3: A2965406916 | GQ3: A2965406312 | GR3: A2965400019 | GS3: A2965406712 | GT3: A2965408712 | GU3: A2965406912 | GV3: A2965408912 | GW3: A2965408312 | GX3: A2965408512 | GY3: A2965407912 | GZ3: A2965409112 | HA3: A2965407015 | HB3: A2965406519 | HC3: =VLOOKUP(HC4,'Acomodos Modularidades'!$A$2:$B$211,2,FALSE) -> A2965408612 | HD3: =VLOOKUP(HD4,'Acomodos Modularidades'!$A$2:$B$211,2,FALSE) -> A2965406812 | HE3: =VLOOKUP(HE4,'Acomodos Modularidades'!$A$2:$B$211,2,FALSE) -> A2965408812 | HF3: =VLOOKUP(HF4,'Acomodos Modularidades'!$A$2:$B$211,2,FALSE) -> A2965408212 | HG3: =VLOOKUP(HG4,'Acomodos Modularidades'!$A$2:$B$211,2,FALSE) -> A2965408412 | HH3: =VLOOKUP(HH4,'Acomodos Modularidades'!$A$2:$B$211,2,FALSE) -> A2965407812 | HI3: =VLOOKUP(HI4,'Acomodos Modularidades'!$A$2:$B$211,2,FALSE) -> A2965409012 | HJ3: =VLOOKUP(HJ4,'Acomodos Modularidades'!$A$2:$B$211,2,FALSE) -> A2965406915 | HK3: =VLOOKUP(HK4,'Acomodos Modularidades'!$A$2:$B$211,2,FALSE) -> A2965406419
